File: Stress and Strain Analysis with Matplotlib/Group 2 Aluminum.csv
Strain : Axial Gauge Length (Strain Source),2,in,
Strain : Time at Removal (Strain Source),,ms,
,,,
Time,Extension,Load,Strain 1
(sec),(in),(lbf),(%)
0,0,0.02136,0.00003
0.2,0.00025,0.12709,0.00013
0.4,0.00064,0.1465,0.00011
0.6,0.00099,0.15982,0.00007
0.8,0.00133,0.14972,0.00008
1,0.00167,0.0579,0.0001
1.2,0.002,0.26995,0.00013
1.4,0.00233,0.34609,0.00013
1.6,0.00266,0.44138,0.00014
1.8,0.003,0.38816,0.00018
2,0.00333,0.9827,0.00035
2.2,0.00367,1.49992,0.00039
2.4,0.004,2.43763,0.00046
2.6,0.00433,3.52875,0.00044
2.8,0.00466,4.61212,0.00054
3,0.005,5.65732,0.00067
3.2,0.00533,6.62765,0.00079
3.4,0.00567,7.65616,0.00084
3.6,0.006,10.9518,0.00105
3.8,0.00633,15.40449,0.0013
4,0.00666,20.81905,0.00167
4.2,0.007,28.31583,0.00207
4.4,0.00733,37.39771,0.00261
4.6,0.00766,47.97154,0.00302
4.8,0.008,60.22676,0.0035
5,0.00833,73.03004,0.00396
5.2,0.00866,87.31697,0.00448
5.4,0.009,102.51349,0.00503
5.6,0.00933,118.16882,0.00557
5.8,0.00966,134.90155,0.00618
6,0.01,152.80568,0.00698
6.2,0.01033,171.31976,0.00773
6.4,0.01067,191.56282,0.00849
6.6,0.011,212.40015,0.00947
6.8,0.01133,235.01209,0.01053
7,0.01166,258.5133,0.01165
7.2,0.012,282.47132,0.01275
7.4,0.01233,307.46681,0.01397
7.6,0.01266,332.29397,0.01522
7.8,0.01299,356.6759,0.0165
8,0.01333,382.00556,0.01782
8.2,0.01366,406.23411,0.01902
8.4,0.014,429.74058,0.02016
8.6,0.01433,452.14614,0.02125
8.8,0.01466,473.62701,0.02226
9,0.01499,494.6638,0.02331
9.2,0.01533,516.69576,0.02447
9.4,0.01567,537.62535,0.02568
9.6,0.016,559.23113,0.02696
9.8,0.01633,580.34672,0.02823
10,0.01666,601.70913,0.02936
10.2,0.017,623.28714,0.03076
10.4,0.01733,645.31939,0.03198
10.6,0.01767,667.01013,0.03317
10.8,0.018,688.70262,0.03441
11,0.01833,711.43682,0.03567
11.2,0.01866,733.6655,0.03694
11.4,0.019,757.2046,0.03813
11.6,0.01934,780.72853,0.03937
11.8,0.01966,804.07894,0.0406
12,0.01999,827.90311,0.04183
12.2,0.02033,852.29869,0.04311
12.4,0.02066,876.34136,0.04429
12.6,0.021,901.55155,0.04562
12.8,0.02133,926.08632,0.04688
13,0.02166,950.87837,0.04816
13.2,0.022,976.50755,0.04955
13.4,0.02233,"1,001.74",0.05091
13.6,0.02266,"1,028.23",0.05219
13.8,0.023,"1,054.47",0.0536
14,0.02333,"1,080.51",0.05497
14.2,0.02366,"1,106.67",0.05635
14.4,0.024,"1,133.94",0.05772
14.6,0.02433,"1,161.24",0.05917
14.8,0.02467,"1,188.73",0.06059
15,0.025,"1,216.27",0.06209
15.2,0.02533,"1,243.48",0.06348
15.4,0.02566,"1,272.12",0.06503
15.6,0.026,"1,300.03",0.06645
15.8,0.02633,"1,328.93",0.06812
16,0.02667,"1,357.65",0.06974
16.2,0.027,"1,386.23",0.07132
16.4,0.02733,"1,415.26",0.07288
16.6,0.02766,"1,445.51",0.07448
16.8,0.028,"1,475.04",0.07608
17,0.02833,"1,505.15",0.07768
17.2,0.02866,"1,535.62",0.07926
17.4,0.029,"1,565.74",0.08085
17.6,0.02933,"1,597.01",0.08238
17.8,0.02966,"1,628.22",0.08396
18,0.03,"1,659.90",0.08553
18.2,0.03033,"1,691.07",0.08714
18.4,0.03066,"1,723.30",0.08868
18.6,0.03099,"1,754.10",0.09022
18.8,0.03133,"1,786.76",0.09183
19,0.03166,"1,818.43",0.09342
19.2,0.032,"1,850.28",0.09499
19.4,0.03233,"1,882.46",0.09652
19.6,0.03266,"1,915.04",0.09813
19.8,0.03299,"1,947.30",0.09962
20,0.03333,"1,980.28",0.10118
20.2,0.03367,"2,012.48",0.10269
20.4,0.034,"2,044.89",0.10414
20.6,0.03433,"2,077.88",0.10568
20.8,0.03466,"2,110.83",0.10713
21,0.035,"2,144.99",0.10878
21.2,0.03533,"2,178.50",0.11033
21.4,0.03566,"2,211.30",0.11196
21.6,0.03599,"2,245.37",0.11348
21.8,0.03633,"2,279.42",0.11519
22,0.03666,"2,312.88",0.11669
22.2,0.037,"2,347.85",0.11834
22.4,0.03733,"2,381.65",0.11987
22.6,0.03766,"2,415.98",0.12144
22.8,0.038,"2,450.01",0.12311
23,0.03833,"2,484.91",0.12472
23.2,0.03866,"2,519.83",0.12634
23.4,0.039,"2,554.80",0.12795
23.6,0.03933,"2,588.93",0.12966
23.8,0.03966,"2,624.27",0.13141
24,0.04,"2,660.26",0.13316
24.2,0.04033,"2,695.87",0.13485
24.4,0.04067,"2,732.33",0.13661
24.6,0.041,"2,767.22",0.13821
24.8,0.04133,"2,803.40",0.13995
25,0.04166,"2,839.86",0.1416
25.2,0.042,"2,875.98",0.14325
25.4,0.04233,"2,912.05",0.14497
25.6,0.04266,"2,948.52",0.14658
25.8,0.04299,"2,984.60",0.14834
26,0.04333,"3,020.90",0.15009
26.2,0.04367,"3,058.58",0.15198
26.4,0.044,"3,095.28",0.15384
26.6,0.04433,"3,132.21",0.15559
26.8,0.04466,"3,169.67",0.15743
27,0.04499,"3,207.17",0.15929
27.2,0.04533,"3,245.74",0.16115
27.4,0.04567,"3,284.40",0.16293
27.6,0.046,"3,322.60",0.16475
27.8,0.04633,"3,361.61",0.16658
28,0.04666,"3,400.64",0.16845
28.2,0.04699,"3,440.35",0.17034
28.4,0.04733,"3,482.09",0.17242
28.6,0.04766,"3,523.19",0.17431
28.8,0.048,"3,564.21",0.17641
29,0.04833,"3,606.71",0.17834
29.2,0.04866,"3,649.01",0.18033
29.4,0.04899,"3,692.09",0.1825
29.6,0.04933,"3,735.81",0.18465
29.8,0.04967,"3,778.84",0.18677
30,0.04999,"3,822.09",0.18882
30.2,0.05033,"3,866.04",0.19082
30.4,0.05066,"3,910.43",0.19301
30.6,0.051,"3,955.86",0.19534
30.8,0.05133,"4,000.12",0.19755
31,0.05166,"4,044.72",0.19964
31.2,0.052,"4,090.26",0.20176
31.4,0.05233,"4,135.50",0.20385
31.6,0.05266,"4,181.21",0.20605
31.8,0.053,"4,228.00",0.20829
32,0.05333,"4,272.45",0.21047
32.2,0.05366,"4,318.34",0.21275
32.4,0.054,"4,365.30",0.21522
32.6,0.05433,"4,411.56",0.21751
32.8,0.05467,"4,458.43",0.21982
33,0.055,"4,504.69",0.22212
33.2,0.05533,"4,550.52",0.22424
33.4,0.05566,"4,597.31",0.22658
33.6,0.056,"4,645.07",0.22881
33.8,0.05633,"4,691.40",0.23105
34,0.05667,"4,738.51",0.23346
34.2,0.057,"4,785.72",0.23575
34.4,0.05733,"4,832.50",0.2381
34.6,0.05766,"4,880.11",0.24043
34.8,0.058,"4,928.11",0.24291
35,0.05833,"4,975.85",0.24526
35.2,0.05866,"5,023.27",0.2476
35.4,0.059,"5,071.11",0.24998
35.6,0.05933,"5,118.94",0.2523
35.8,0.05967,"5,167.91",0.25478
36,0.06,"5,215.42",0.2571
36.2,0.06033,"5,263.46",0.25951
36.4,0.06066,"5,312.29",0.26186
36.6,0.06099,"5,359.68",0.26413
36.8,0.06133,"5,408.87",0.26649
37,0.06167,"5,458.57",0.26886
37.2,0.062,"5,506.30",0.27123
37.4,0.06233,"5,555.36",0.27368
37.6,0.06266,"5,604.67",0.27619
37.8,0.06299,"5,652.85",0.27862
38,0.06333,"5,703.21",0.28114
38.2,0.06367,"5,752.24",0.28342
38.4,0.06399,"5,799.82",0.28567
38.6,0.06433,"5,849.81",0.28802
38.8,0.06466,"5,899.32",0.29047
39,0.06499,"5,948.73",0.2928
39.2,0.06534,"5,999.39",0.29534
39.4,0.06566,"6,048.06",0.29783
39.6,0.06599,"6,097.68",0.30026
39.8,0.06633,"6,148.65",0.30279
40,0.06666,"6,198.87",0.30519
40.2,0.067,"6,249.62",0.30761
40.4,0.06733,"6,299.65",0.31001
40.6,0.06766,"6,349.51",0.31235
40.8,0.068,"6,400.24",0.31496
41,0.06833,"6,451.04",0.31752
41.2,0.06866,"6,501.12",0.31997
41.4,0.069,"6,552.20",0.32249
41.6,0.06933,"6,602.75",0.32493
41.8,0.06966,"6,653.40",0.32745
42,0.07,"6,705.73",0.33001
42.2,0.07033,"6,756.78",0.33258
42.4,0.07066,"6,807.28",0.3351
42.6,0.071,"6,858.17",0.3377
42.8,0.07133,"6,908.94",0.34032
43,0.07166,"6,959.57",0.34296
43.2,0.072,"7,011.63",0.3455
43.4,0.07233,"7,062.41",0.34814
43.6,0.07266,"7,113.22",0.35066
43.8,0.07299,"7,164.65",0.35333
44,0.07333,"7,215.40",0.35592
44.2,0.07366,"7,267.37",0.3585
44.4,0.074,"7,318.67",0.36115
44.6,0.07433,"7,369.09",0.36382
44.8,0.07466,"7,420.30",0.36648
45,0.07499,"7,471.14",0.36902
45.2,0.07533,"7,522.13",0.37157
45.4,0.07567,"7,574.26",0.37424
45.6,0.076,"7,624.88",0.3769
45.8,0.07633,"7,675.37",0.37947
46,0.07666,"7,727.49",0.38232
46.2,0.07699,"7,777.64",0.38503
46.4,0.07733,"7,829.00",0.38766
46.6,0.07767,"7,880.95",0.39039
46.8,0.07799,"7,930.73",0.39297
47,0.07833,"7,981.79",0.39574
47.2,0.07866,"8,032.73",0.39861
47.4,0.07899,"8,082.68",0.40128
47.6,0.07933,"8,134.19",0.40414
47.8,0.07967,"8,184.50",0.40695
48,0.07999,"8,234.03",0.4098
48.2,0.08033,"8,284.23",0.41276
48.4,0.08066,"8,334.54",0.41572
48.6,0.081,"8,384.50",0.41879
48.8,0.08133,"8,433.40",0.42199
49,0.08166,"8,481.94",0.42524
49.2,0.08199,"8,530.54",0.42858
49.4,0.08233,"8,578.50",0.43205
49.6,0.08266,"8,625.97",0.43557
49.8,0.083,"8,673.44",0.43951
50,0.08333,"8,719.44",0.44346
50.2,0.08366,"8,764.66",0.44744
50.4,0.08399,"8,809.93",0.45156
50.6,0.08433,"8,854.82",0.45597
50.8,0.08466,"8,897.89",0.4606
51,0.085,"8,940.58",0.46551
51.2,0.08533,"8,981.71",0.47049
51.4,0.08566,"9,021.98",0.47559
51.6,0.086,"9,063.07",0.48105
51.8,0.08633,"9,101.10",0.48695
52,0.08666,"9,138.37",0.49296
52.2,0.087,"9,174.64",0.49936
52.4,0.08733,"9,208.43",0.50618
52.6,0.08766,"9,240.55",0.51326
52.8,0.088,"9,272.02",0.52113
53,0.08833,"9,298.92",0.52956
53.2,0.08866,"9,323.34",0.5382
53.4,0.089,"9,345.90",0.54795
53.6,0.08933,"9,364.93",0.55812
53.8,0.08967,"9,382.34",0.56878
54,0.08999,"9,396.64",0.58008
54.2,0.09033,"9,408.89",0.59191
54.4,0.09067,"9,420.59",0.60409
54.6,0.091,"9,429.36",0.61687
54.8,0.09133,"9,438.12",0.62965
55,0.09167,"9,447.02",0.64289
55.2,0.092,"9,453.00",0.65613
55.4,0.09233,"9,459.10",0.66954
55.6,0.09267,"9,465.60",0.68316
55.8,0.093,"9,470.51",0.69709
56,0.09333,"9,476.49",0.71073
56.2,0.09367,"9,482.42",0.72471
56.4,0.094,"9,485.88",0.73872
56.6,0.09433,"9,490.17",0.75281
56.8,0.09466,"9,494.97",0.76711
57,0.095,"9,499.44",0.78143
57.2,0.09533,"9,503.69",0.79571
57.4,0.09567,"9,506.57",0.81025
57.6,0.096,"9,510.12",0.82453
57.8,0.09633,"9,514.46",0.83919
58,0.09666,"9,517.40",0.85373
58.2,0.097,"9,521.37",0.86822
58.4,0.09734,"9,525.18",0.88288
58.6,0.09766,"9,526.97",0.89742
58.8,0.098,"9,530.49",0.91191
59,0.09833,"9,534.29",0.92681
59.2,0.09866,"9,537.00",0.94132
59.4,0.099,"9,540.71",0.95592
59.6,0.09934,"9,543.80",0.97064
59.8,0.09966,"9,545.94",0.9854
60,0.1,"9,549.57",0.99994
60.2,0.10033,"9,552.66",1.01479
60.4,0.10067,"9,555.40",1.02948
60.6,0.101,"9,558.35",1.04422
60.8,0.10133,"9,560.43",1.05896
61,0.10166,"9,563.80",1.07371
61.2,0.102,"9,567.55",1.08865
61.4,0.10233,"9,569.87",1.10328
61.6,0.10267,"9,572.07",1.11797
61.8,0.103,"9,575.19",1.13271
62,0.10333,"9,577.20",1.14752
62.2,0.10366,"9,580.90",1.16215
62.4,0.104,"9,584.63",1.17699
62.6,0.10433,"9,586.14",1.19159
62.8,0.10466,"9,589.28",1.20646
63,0.105,"9,592.20",1.22132
63.2,0.10533,"9,594.34",1.2361
63.4,0.10567,"9,597.72",1.251
63.6,0.106,"9,600.17",1.26581
63.8,0.10633,"9,601.69",1.28025
64,0.10667,"9,605.13",1.29524
64.2,0.10699,"9,607.68",1.31007
64.4,0.10733,"9,610.48",1.32466
64.60001,0.10767,"9,614.60",1.33966
64.8,0.108,"9,615.98",1.35447
65,0.10833,"9,618.61",1.36922
65.2,0.10867,"9,622.01",1.38399
65.4,0.109,"9,624.08",1.39883
65.60001,0.10933,"9,627.61",1.41346
65.8,0.10967,"9,630.11",1.42836
66,0.10999,"9,631.49",1.44293
66.20001,0.11033,"9,634.68",1.45774
66.4,0.11066,"9,637.63",1.47241
66.60001,0.111,"9,640.30",1.48714
66.8,0.11134,"9,643.41",1.5019
67,0.11166,"9,645.07",1.51656
67.20001,0.11199,"9,647.42",1.5313
67.4,0.11233,"9,651.31",1.54626
67.60001,0.11266,"9,653.21",1.56112
67.8,0.113,"9,656.13",1.57578
68,0.11334,"9,659.11",1.5906
68.20001,0.11366,"9,660.27",1.60544
68.4,0.114,"9,663.08",1.61993
68.60001,0.11433,"9,666.74",1.63486
68.8,0.11466,"9,668.75",1.64942
69,0.115,"9,671.34",1.66409
69.20001,0.11533,"9,674.25",1.67901
69.4,0.11566,"9,675.95",1.69367
69.60001,0.116,"9,679.34",1.70838
69.8,0.11633,"9,682.27",1.72317
70,0.11667,"9,684.19",1.73783
70.20001,0.117,"9,686.97",1.7525
70.4,0.11733,"9,689.14",1.76733
70.60001,0.11766,"9,691.42",1.78194
70.8,0.118,"9,695.23",1.79676
71,0.11833,"9,697.27",1.81149
71.20001,0.11866,"9,698.77",1.82598
71.4,0.119,"9,701.94",1.84077
71.60001,0.11933,"9,704.09",1.85535
71.8,0.11966,"9,707.19",1.87018
72,0.12001,"9,710.65",1.88503
72.20001,0.12033,"9,711.28",1.89965
72.4,0.12066,"9,714.37",1.91431
72.60001,0.121,"9,717.26",1.92913
72.8,0.12133,"9,718.90",1.94385
73,0.12167,"9,722.94",1.95846
73.20001,0.122,"9,724.84",1.97326
73.4,0.12233,"9,726.46",1.98794
73.60001,0.12266,"9,729.58",2.00261
73.8,0.123,"9,731.89",2.01748
74,0.12333,"9,734.53",2.03214
74.20001,0.12367,"9,737.77",2.04702
74.4,0.124,"9,738.81",2.06163
74.60001,0.12433,"9,740.57",2.07619
74.8,0.12467,"9,744.35",2.091
75,0.125,"9,746.49",2.10567
75.20001,0.12533,"9,749.48",2.12041
75.4,0.12567,"9,751.57",2.13521
75.60001,0.126,"9,753.25",2.14984
75.8,0.12633,"9,755.90",2.16451
76,0.12666,"9,758.38",2.17917
76.20001,0.12699,"9,760.71",2.19377
76.4,0.12733,"9,763.28",2.20838
76.60001,0.12766,"9,765.26",2.22297
76.8,0.12799,"9,767.36",2.23768
77,0.12833,"9,770.69",2.25239
77.20001,0.12867,"9,773.09",2.26714
77.4,0.129,"9,774.87",2.28166
77.60001,0.12933,"9,777.55",2.29649
77.8,0.12966,"9,778.78",2.31111
78,0.13,"9,781.93",2.3259
78.20001,0.13034,"9,784.99",2.34057
78.4,0.13067,"9,786.43",2.35533
78.60001,0.131,"9,788.16",2.36987
78.8,0.13133,"9,790.75",2.38461
79,0.13166,"9,792.72",2.39922
79.20001,0.132,"9,795.61",2.41385
79.4,0.13233,"9,798.64",2.4287
79.60001,0.13266,"9,799.37",2.44329
79.8,0.133,"9,802.66",2.45807
80,0.13333,"9,804.19",2.47279
80.20001,0.13366,"9,806.20",2.48735
80.4,0.134,"9,810.06",2.50201
80.60001,0.13433,"9,811.01",2.51662
80.8,0.13466,"9,812.57",2.53121
81.00001,0.135,"9,816.19",2.54604
81.20001,0.13533,"9,817.39",2.56054
81.4,0.13566,"9,820.05",2.57527
81.60001,0.136,"9,822.77",2.58981
81.8,0.13633,"9,823.78",2.60451
82.00001,0.13666,"9,826.49",2.61907
82.20001,0.137,"9,829.22",2.63404
82.4,0.13733,"9,830.97",2.6486
82.60001,0.13767,"9,833.44",2.66342
82.8,0.138,"9,834.97",2.67814
83.00001,0.13833,"9,836.28",2.69282
83.20001,0.13866,"9,838.82",2.70744
83.4,0.139,"9,841.24",2.72208
83.60001,0.13933,"9,843.44",2.73671
83.8,0.13967,"9,845.71",2.75139
84.00001,0.13999,"9,847.15",2.76611
84.20001,0.14033,"9,849.23",2.78091
84.4,0.14067,"9,852.41",2.79567
84.60001,0.141,"9,854.50",2.81045
84.8,0.14133,"9,855.68",2.82508
85.00001,0.14167,"9,857.85",2.83978
85.20001,0.142,"9,859.06",2.85442
85.4,0.14233,"9,861.56",2.86914
85.60001,0.14267,"9,864.38",2.88376
85.8,0.143,"9,866.18",2.89852
86.00001,0.14333,"9,868.01",2.91329
86.20001,0.14366,"9,869.69",2.92809
86.4,0.14399,"9,871.42",2.94271
86.60001,0.14433,"9,874.62",2.95751
86.8,0.14467,"9,876.46",2.97228
87.00001,0.145,"9,877.60",2.98691
87.20001,0.14534,"9,880.50",3.00181
87.4,0.14567,"9,881.33",3.01666
87.60001,0.14599,"9,883.53",3.03136
87.8,0.14634,"9,886.80",3.04606
88.00001,0.14667,"9,887.39",3.06076
88.20001,0.147,"9,889.26",3.07555
88.4,0.14733,"9,891.96",3.09038
88.60001,0.14766,"9,892.85",3.10515
88.8,0.148,"9,895.36",3.12004
89.00001,0.14833,"9,897.60",3.13482
89.20001,0.14866,"9,898.01",3.14955
89.4,0.149,"9,900.70",3.16426
89.60001,0.14933,"9,902.67",3.1793
89.8,0.14966,"9,904.39",3.19383
90.00001,0.15,"9,907.19",3.20873
90.20001,0.15033,"9,907.99",3.22352
90.4,0.15066,"9,909.51",3.23829
90.60001,0.151,"9,912.08",3.25302
90.8,0.15133,"9,913.17",3.268
91.00001,0.15167,"9,915.31",3.28271
91.20001,0.152,"9,917.44",3.29764
91.4,0.15233,"9,917.51",3.3122
91.60001,0.15266,"9,919.96",3.32706
91.8,0.153,"9,922.28",3.34186
92.00001,0.15333,"9,924.15",3.35677
92.20001,0.15367,"9,925.98",3.37141
92.4,0.154,"9,927.59",3.38647
92.60001,0.15433,"9,928.62",3.40121
92.8,0.15466,"9,930.78",3.41602
93.00001,0.155,"9,932.87",3.43092
93.20001,0.15533,"9,933.76",3.4458
93.4,0.15566,"9,935.61",3.46046
93.60001,0.156,"9,936.95",3.47546
93.8,0.15633,"9,938.98",3.49015
94.00001,0.15667,"9,941.57",3.50513
94.20001,0.157,"9,942.71",3.51988
94.4,0.15733,"9,944.29",3.53484
94.60001,0.15767,"9,946.49",3.54988
94.8,0.15799,"9,947.25",3.56471
95.00001,0.15833,"9,949.31",3.5796
95.20001,0.15867,"9,951.41",3.59464
95.4,0.159,"9,951.68",3.60938
95.60001,0.15933,"9,954.09",3.62401
95.8,0.15967,"9,955.17",3.63907
96.00001,0.16,"9,956.66",3.65402
96.20001,0.16033,"9,959.61",3.66886
96.4,0.16067,"9,960.57",3.68368
96.60001,0.161,"9,960.85",3.69861
96.8,0.16133,"9,963.25",3.71339
97.00001,0.16166,"9,964.40",3.72828
97.20001,0.162,"9,966.25",3.74311
97.4,0.16234,"9,968.38",3.75818
97.60001,0.16267,"9,968.83",3.77301
97.8,0.163,"9,970.18",3.78782
98.00001,0.16333,"9,971.88",3.80276
98.20001,0.16366,"9,973.30",3.81766
98.4,0.164,"9,975.59",3.8324
98.60001,0.16433,"9,976.58",3.84745
98.8,0.16466,"9,977.05",3.86244
99.00001,0.165,"9,979.32",3.87743
99.20001,0.16533,"9,980.56",3.89234
99.4,0.16566,"9,981.97",3.90731
99.60001,0.166,"9,983.81",3.92238
99.8,0.16633,"9,984.52",3.93721
100.00001,0.16666,"9,985.34",3.95203
100.20001,0.167,"9,988.01",3.96721
100.4,0.16733,"9,989.35",3.98214
100.60001,0.16766,"9,989.55",3.99694
100.8,0.168,"9,992.25",4.01193
101.00001,0.16833,"9,992.72",4.02709
101.20001,0.16866,"9,993.66",4.04171
101.4,0.169,"9,995.93",4.05679
101.60001,0.16933,"9,997.32",4.07167
101.8,0.16967,"9,998.15",4.0868
102.00001,0.17,"9,999.38",4.10153
102.20001,0.17033,"10,000.25",4.11665
102.4,0.17067,"10,003.11",4.13159
102.60001,0.171,"10,003.70",4.14677
102.8,0.17133,"10,004.86",4.16142
103.00001,0.17167,"10,006.67",4.1767
103.20001,0.172,"10,006.46",4.19172
103.4,0.17233,"10,007.90",4.20658
103.60001,0.17267,"10,010.64",4.22163
103.8,0.173,"10,010.84",4.23672
104.00001,0.17333,"10,011.43",4.25162
104.20001,0.17367,"10,013.56",4.2666
104.4,0.17399,"10,013.71",4.28156
104.60001,0.17433,"10,015.56",4.29662
104.8,0.17467,"10,017.37",4.31155
105.00001,0.175,"10,017.51",4.32621
105.20001,0.17533,"10,019.09",4.34134
105.4,0.17567,"10,020.35",4.35664
105.60001,0.176,"10,021.42",4.37149
105.8,0.17633,"10,022.95",4.38645
106.00001,0.17667,"10,023.53",4.40149
106.20001,0.177,"10,024.05",4.41646
106.4,0.17733,"10,025.78",4.43159
106.60001,0.17766,"10,026.76",4.44668
106.8,0.178,"10,027.76",4.46159
107.00001,0.17834,"10,029.76",4.47668
107.20001,0.17866,"10,029.68",4.4915
107.4,0.17899,"10,030.93",4.50656
107.60001,0.17933,"10,033.09",4.5218
107.8,0.17967,"10,033.51",4.53677
108.00001,0.18,"10,034.94",4.55177
108.20001,0.18034,"10,035.56",4.56689
108.4,0.18066,"10,035.64",4.58186
108.60001,0.181,"10,037.49",4.59691
108.8,0.18133,"10,038.91",4.61203
109.00001,0.18166,"10,039.74",4.62717
109.20001,0.182,"10,040.99",4.64225
109.4,0.18233,"10,041.45",4.65732
109.60001,0.18266,"10,041.91",4.67248
109.8,0.183,"10,043.97",4.68777
110.00001,0.18333,"10,044.69",4.70294
110.20001,0.18366,"10,045.07",4.71779
110.4,0.184,"10,046.24",4.73299
110.60001,0.18433,"10,046.43",4.74815
110.8,0.18466,"10,047.51",4.76331
111.00001,0.185,"10,048.90",4.77823
111.20001,0.18533,"10,049.96",4.79362
111.4,0.18567,"10,050.99",4.8086
111.60001,0.186,"10,051.84",4.82383
111.8,0.18633,"10,052.29",4.83897
112.00001,0.18667,"10,053.74",4.85422
112.20001,0.187,"10,054.74",4.86944
112.4,0.18733,"10,054.13",4.88431
112.60001,0.18766,"10,056.14",4.89959
112.8,0.188,"10,056.65",4.91485
113.00001,0.18833,"10,057.64",4.93015
113.20001,0.18867,"10,059.62",4.94527
113.40001,0.189,"10,059.24",4.9606
113.60001,0.18933,"10,059.27",4.97559
113.8,0.18967,"10,060.89",4.9911
114.00001,0.19,"10,061.79",5.00616
114.20001,0.19033,"10,062.76",5.02155
114.40001,0.19067,"10,063.62",5.03674
114.60001,0.191,"10,063.39",5.05188
114.8,0.19133,"10,064.49",5.06702
115.00001,0.19166,"10,065.30",5.08242
115.20001,0.19199,"10,066.15",5.09772
115.40001,0.19233,"10,067.71",5.11283
115.60001,0.19267,"10,067.80",5.12815
115.8,0.193,"10,068.06",5.14328
116.00001,0.19333,"10,069.14",5.1588
116.20001,0.19366,"10,069.50",5.17388
116.40001,0.194,"10,070.22",5.18917
116.60001,0.19434,"10,071.29",5.20449
116.8,0.19466,"10,071.07",5.21975
117.00001,0.195,"10,071.90",5.23473
117.20001,0.19534,"10,073.72",5.25036
117.40001,0.19566,"10,074.17",5.26569
117.60001,0.196,"10,074.83",5.28095
117.8,0.19633,"10,075.21",5.29625
118.00001,0.19666,"10,075.18",5.31156
118.20001,0.197,"10,076.55",5.327
118.40001,0.19733,"10,077.18",5.34237
118.60001,0.19767,"10,077.37",5.35751
118.8,0.198,"10,077.76",5.37265
119.00001,0.19833,"10,078.57",5.38803
119.20001,0.19866,"10,079.04",5.40337
119.40001,0.199,"10,080.54",5.4186
119.60001,0.19933,"10,080.96",5.43414
119.8,0.19967,"10,081.61",5.44945
120.00001,0.2,"10,082.12",5.465
120.20001,0.20033,"10,081.85",5.48014
120.40001,0.20066,"10,083.18",5.49572
120.60001,0.201,"10,083.82",5.51106
120.8,0.20133,"10,083.55",5.5264
121.00001,0.20166,"10,084.23",5.54157
121.20001,0.202,"10,084.47",5.55711
121.40001,0.20233,"10,085.04",5.57247
121.60001,0.20267,"10,086.93",5.58792
121.8,0.203,"10,086.85",5.60334
122.00001,0.20333,"10,086.51",5.61873
122.20001,0.20367,"10,087.67",5.63426
122.40001,0.204,"10,087.53",5.64954
122.60001,0.20433,"10,087.98",5.66499
122.8,0.20467,"10,089.75",5.68051
123.00001,0.205,"10,088.72",5.69598
123.20001,0.20533,"10,089.00",5.71123
123.40001,0.20567,"10,090.36",5.72681
123.60001,0.206,"10,090.53",5.74239
123.8,0.20633,"10,091.38",5.75778
124.00001,0.20667,"10,091.53",5.77336
124.20001,0.20699,"10,091.44",5.78868
124.40001,0.20733,"10,092.17",5.80438
124.60001,0.20766,"10,092.45",5.81989
124.8,0.208,"10,093.28",5.83545
125.00001,0.20834,"10,094.00",5.85087
125.20001,0.20866,"10,093.27",5.86654
125.40001,0.20899,"10,093.24",5.88207
125.60001,0.20933,"10,094.82",5.89763
125.8,0.20966,"10,094.57",5.91323
126.00001,0.21,"10,095.08",5.92873
126.20001,0.21034,"10,095.70",5.94451
126.40001,0.21066,"10,094.71",5.9597
126.60001,0.211,"10,095.13",5.9752
126.8,0.21133,"10,096.54",5.99086
127.00001,0.21167,"10,096.49",6.00659
127.20001,0.212,"10,096.26",6.02182
127.40001,0.21233,"10,096.85",6.03739
127.60001,0.21266,"10,096.97",6.05298
127.8,0.213,"10,097.24",6.06855
128,0.21333,"10,098.07",6.0842
128.20002,0.21367,"10,098.02",6.09958
128.40001,0.214,"10,098.48",6.11521
128.60001,0.21433,"10,098.06",6.13091
128.8,0.21466,"10,098.46",6.14654
129,0.215,"10,100.08",6.16228
129.20002,0.21533,"10,099.26",6.17789
129.40001,0.21566,"10,098.52",6.19355
129.60001,0.216,"10,100.18",6.20925
129.8,0.21633,"10,099.52",6.22489
130,0.21666,"10,099.90",6.24051
130.20002,0.217,"10,101.12",6.25653
130.40001,0.21733,"10,099.84",6.27209
130.60001,0.21766,"10,099.99",6.28769
130.8,0.218,"10,100.46",6.30354
131,0.21833,"10,100.43",6.31924
131.20002,0.21867,"10,102.17",6.33513
131.40002,0.219,"10,101.07",6.35076
131.6,0.21933,"10,099.97",6.36651
131.8,0.21967,"10,101.43",6.38214
132,0.22,"10,100.77",6.3982
132.20002,0.22033,"10,101.03",6.41358
132.40002,0.22067,"10,102.19",6.42941
132.6,0.221,"10,101.02",6.44507
132.8,0.22133,"10,101.09",6.46077
133,0.22167,"10,101.72",6.47644
133.20002,0.222,"10,101.48",6.49213
133.40002,0.22233,"10,101.86",6.50782
133.6,0.22267,"10,102.12",6.52371
133.8,0.223,"10,101.81",6.53944
134,0.22333,"10,101.79",6.55525
134.20002,0.22367,"10,102.45",6.57104
134.40002,0.224,"10,102.13",6.5869
134.6,0.22433,"10,101.74",6.60251
134.8,0.22466,"10,102.26",6.61852
135,0.22499,"10,101.53",6.63412
135.20002,0.22533,"10,102.51",6.6503
135.40002,0.22567,"10,102.27",6.66612
135.6,0.226,"10,101.40",6.68179
135.8,0.22633,"10,101.48",6.69747
136,0.22666,"10,101.17",6.71315
136.20002,0.227,"10,101.37",6.72909
136.40002,0.22734,"10,102.93",6.7452
136.6,0.22767,"10,102.11",6.76121
136.8,0.228,"10,101.05",6.77661
137,0.22833,"10,101.67",6.79261
137.20002,0.22866,"10,101.10",6.8083
137.40002,0.229,"10,101.64",6.82427
137.6,0.22934,"10,101.88",6.8401
137.8,0.22966,"10,100.65",6.85599
138,0.23,"10,101.02",6.87174
138.20002,0.23033,"10,100.45",6.88767
138.40002,0.23066,"10,100.51",6.90348
138.6,0.231,"10,102.08",6.91952
138.8,0.23133,"10,100.92",6.93543
139,0.23166,"10,100.31",6.95133
139.20002,0.232,"10,100.94",6.96725
139.40002,0.23233,"10,100.04",6.98333
139.6,0.23267,"10,100.22",6.9992
139.8,0.233,"10,100.39",7.01518
140,0.23333,"10,099.50",7.03093
140.20002,0.23366,"10,099.50",7.04693
140.40002,0.234,"10,099.45",7.06302
140.6,0.23433,"10,098.92",7.07891
140.8,0.23467,"10,099.65",7.09491
141,0.235,"10,099.05",7.1108
141.20002,0.23533,"10,098.02",7.1269
141.40002,0.23566,"10,098.49",7.14281
141.6,0.236,"10,098.53",7.15903
141.8,0.23633,"10,098.19",7.17494
142,0.23667,"10,097.99",7.19094
142.20002,0.23699,"10,096.96",7.20675
142.40002,0.23733,"10,096.69",7.22293
142.6,0.23767,"10,097.23",7.23894
142.8,0.238,"10,096.96",7.25506
143,0.23833,"10,096.77",7.27107
143.20002,0.23867,"10,096.18",7.2872
143.40002,0.23899,"10,095.15",7.30319
143.6,0.23933,"10,095.50",7.3193
143.8,0.23967,"10,095.76",7.33549
144,0.24,"10,094.99",7.3514
144.20002,0.24033,"10,094.77",7.36757
144.40002,0.24066,"10,094.14",7.38368
144.6,0.24099,"10,093.16",7.39983
144.8,0.24133,"10,094.49",7.41606
145,0.24167,"10,093.87",7.43226
145.20002,0.242,"10,092.65",7.44819
145.40002,0.24233,"10,092.72",7.4646
145.6,0.24266,"10,091.89",7.48075
145.8,0.243,"10,091.43",7.49707
146,0.24333,"10,091.53",7.51329
146.20002,0.24366,"10,090.24",7.52931
146.40002,0.244,"10,090.10",7.54534
146.6,0.24433,"10,089.82",7.56157
146.8,0.24466,"10,089.46",7.57787
147,0.245,"10,089.50",7.59392
147.20002,0.24533,"10,088.61",7.61031
147.40002,0.24566,"10,087.33",7.62623
147.6,0.246,"10,087.78",7.64262
147.8,0.24633,"10,086.91",7.65873
148,0.24666,"10,086.91",7.67499
148.20002,0.247,"10,087.20",7.69123
148.40002,0.24733,"10,085.37",7.70752
148.6,0.24766,"10,084.90",7.7236
148.8,0.248,"10,085.24",7.74
149,0.24833,"10,084.61",7.75637
149.20002,0.24867,"10,084.83",7.77258
149.40002,0.249,"10,084.21",7.78888
149.6,0.24933,"10,082.04",7.80517
149.8,0.24966,"10,082.03",7.82141
150,0.25,"10,081.98",7.83778
150.20002,0.25033,"10,081.46",7.85415
150.40002,0.25067,"10,081.03",7.87045
150.6,0.251,"10,080.28",7.88697
150.8,0.25133,"10,079.00",7.90317
151,0.25167,"10,079.31",7.9196
151.20002,0.252,"10,078.34",7.93588
151.40002,0.25233,"10,077.49",7.95214
151.6,0.25267,"10,077.27",7.96856
151.8,0.25299,"10,075.41",7.98487
152,0.25333,"10,075.11",8.00129
152.20002,0.25367,"10,075.43",8.01754
152.40002,0.25399,"10,073.76",8.03368
152.6,0.25433,"10,073.60",8.04993
152.8,0.25467,"10,073.02",8.06648
153,0.25499,"10,071.22",8.08285
153.20002,0.25533,"10,071.90",8.09929
153.40002,0.25567,"10,071.57",8.11581
153.6,0.256,"10,070.06",8.13214
153.8,0.25633,"10,069.63",8.14853
154,0.25666,"10,068.27",8.16496
154.20002,0.257,"10,067.92",8.18153
154.40002,0.25733,"10,067.97",8.19795
154.6,0.25767,"10,066.53",8.21422
154.8,0.258,"10,065.41",8.23064
155,0.25833,"10,065.00",8.24723
155.20002,0.25866,"10,063.90",8.25617
155.40002,0.259,"10,063.56",8.2725
155.6,0.25934,"10,063.65",7.86766
155.8,0.25966,"10,061.40",7.87458
156,0.26,"10,060.92",7.91441
156.20002,0.26033,"10,060.14",7.86436
156.40002,0.26066,"10,059.04",7.83451
156.6,0.261,"10,058.86",7.81324
156.8,0.26133,"10,057.55",7.7764
157,0.26166,"10,055.22",7.89195
157.20002,0.262,"10,055.54",7.9095
157.40002,0.26233,"10,053.90",7.94554
157.6,0.26266,"10,053.06",7.89777
157.8,0.263,"10,053.55",7.63827
158,0.26333,"10,051.53",7.62554
158.20002,0.26366,"10,050.14",7.70125
158.40002,0.264,"10,050.55",7.67708
158.6,0.26433,"10,049.29",7.85297
158.8,0.26467,"10,048.57",7.73964
159,0.265,"10,047.28",7.73042
159.20002,0.26533,"10,045.40",7.67259
159.40002,0.26567,"10,045.12",-0.26934
159.6,0.266,"10,044.67",-1.93734
159.8,0.26633,"10,043.41",-4.56541
160,0.26667,"10,042.08",-4.0483
160.20002,0.267,"10,040.48",-3.55802
160.40002,0.26733,"10,038.83",-6.30259
160.6,0.26767,"10,039.02",-0.83636
160.8,0.268,"10,037.76",-0.88799
161.00002,0.26833,"10,036.47",-1.05206
161.20002,0.26867,"10,035.59",-1.13369
161.40002,0.269,"10,033.78",-0.80393
161.6,0.26933,"10,033.06",-0.98623
161.8,0.26967,"10,032.68",-0.90738
162.00002,0.27,"10,031.00",-1.23653
162.20002,0.27033,"10,029.22",-1.31251
162.40002,0.27067,"10,028.18",-1.20126
162.6,0.27099,"10,025.84",-1.27794
162.8,0.27133,"10,025.22",-1.27174
163.00002,0.27167,"10,024.74",-1.3363
163.20002,0.272,"10,022.20",-1.27532
163.40002,0.27233,"10,021.59",-1.29864
163.6,0.27267,"10,020.46",-1.29978
163.8,0.273,"10,019.21",-1.29032
164.00002,0.27333,"10,018.50",-1.29557
164.20002,0.27366,"10,016.09",-1.29823
164.40002,0.27399,"10,014.36",-1.29917
164.6,0.27433,"10,013.97",-1.29462
164.8,0.27466,"10,011.89",-1.29528
165.00002,0.275,"10,010.47",-1.3069
165.20002,0.27534,"10,009.56",-1.28085
165.40002,0.27566,"10,006.20",-1.30057
165.6,0.27599,"10,005.01",-1.2997
165.8,0.27633,"10,004.87",-1.29428
166.00002,0.27666,"10,002.85",-1.30445
166.20002,0.277,"10,002.15",-1.29658
166.40002,0.27734,"9,999.49",-1.30006
166.6,0.27766,"9,997.23",-1.29945
166.8,0.278,"9,996.52",-1.29916
167.00002,0.27833,"9,994.42",-1.2988
167.20002,0.27866,"9,992.60",-1.3007
167.40002,0.279,"9,991.52",-1.29285
167.6,0.27933,"9,988.62",-1.29618
167.8,0.27966,"9,986.43",-1.30047
168.00002,0.28,"9,985.90",-1.29793
168.20002,0.28033,"9,984.17",-1.30238
168.40002,0.28067,"9,981.96",-1.29393
168.6,0.281,"9,980.16",-1.29556
168.8,0.28133,"9,978.01",-1.30065
169.00002,0.28166,"9,976.61",-1.29822
169.20002,0.282,"9,974.61",-1.29802
169.40002,0.28233,"9,972.64",-1.30439
169.6,0.28267,"9,970.23",-1.29585
169.8,0.28299,"9,968.37",-1.29705
170.00002,0.28333,"9,966.23",-1.30506
170.20002,0.28367,"9,965.28",-1.29651
170.40002,0.284,"9,962.89",-1.29691
170.6,0.28433,"9,959.90",-1.29564
170.8,0.28467,"9,958.64",-1.30078
171.00002,0.285,"9,955.64",-1.30277
171.20002,0.28533,"9,953.75",-1.29262
171.40002,0.28567,"9,952.66",-1.29923
171.6,0.286,"9,949.50",-1.3015
171.8,0.28633,"9,946.22",-1.29915
172.00002,0.28666,"9,944.95",-1.29446
172.20002,0.287,"9,942.57",-1.30171
172.40002,0.28733,"9,940.38",-1.30264
172.6,0.28767,"9,938.17",-1.29535
172.8,0.288,"9,934.76",-1.30353
173.00002,0.28833,"9,932.45",-1.29678
173.20002,0.28866,"9,929.92",-1.29808
173.40002,0.289,"9,927.43",-1.30493
173.6,0.28933,"9,925.88",-1.29798
173.8,0.28967,"9,922.38",-1.2985
174.00002,0.29,"9,919.49",-1.30498
174.20002,0.29033,"9,917.85",-1.29684
174.40002,0.29066,"9,914.64",-1.29826
174.6,0.291,"9,912.44",-1.30569
174.8,0.29134,"9,910.20",-1.29523
175.00002,0.29166,"9,906.08",-1.29936
175.20002,0.292,"9,903.82",-1.29947
175.40002,0.29233,"9,901.77",-1.29907
175.6,0.29266,"9,898.75",-1.30315
175.8,0.293,"9,896.15",-1.30393
176.00002,0.29333,"9,893.46",-1.30611
176.20002,0.29366,"9,889.61",-1.30023
176.40002,0.294,"9,887.57",-1.29711
176.6,0.29433,"9,885.10",-1.30241
176.8,0.29467,"9,881.72",-1.3071
177.00002,0.295,"9,878.03",-1.29352
177.20002,0.29533,"9,875.06",-1.29878
177.40002,0.29566,"9,872.08",-1.30687
177.6,0.296,"9,869.82",-1.30078
177.8,0.29633,"9,866.41",-1.30096
178.00002,0.29667,"9,862.37",-1.30047
178.20002,0.297,"9,859.72",-1.3012
178.40002,0.29733,"9,856.23",-1.29465
178.6,0.29766,"9,853.73",-1.3053
178.8,0.298,"9,851.26",-1.3021
179.00002,0.29833,"9,847.41",-1.2958
179.20002,0.29866,"9,843.81",-1.30496
179.40002,0.299,"9,840.74",-1.30702
179.6,0.29933,"9,836.77",-1.30152
179.8,0.29967,"9,834.60",-1.29966
180.00002,0.3,"9,831.14",-1.30783
180.20002,0.30033,"9,826.56",-1.29076
180.40002,0.30067,"9,824.22",-1.30909
180.6,0.301,"9,820.19",-1.29742
180.8,0.30133,"9,817.00",-1.29252
181.00002,0.30167,"9,814.43",-1.30582
181.20002,0.302,"9,809.56",-1.30093
181.40002,0.30233,"9,805.86",-1.30169
181.6,0.30267,"9,803.02",-1.30165
181.8,0.303,"9,799.25",-1.2997
182.00002,0.30333,"9,795.69",-1.30363
182.20002,0.30367,"9,791.61",-1.3009
182.40002,0.30399,"9,787.06",-1.29831
182.6,0.30433,"9,784.41",-1.30769
182.8,0.30467,"9,781.16",-1.29733
183.00002,0.305,"9,777.86",-1.30223
183.20002,0.30534,"9,774.38",-1.30439
183.40002,0.30567,"9,769.82",-1.30265
183.6,0.306,"9,765.17",-1.29932
183.8,0.30633,"9,762.76",-1.30406
184.00002,0.30666,"9,758.40",-1.30357
184.20002,0.307,"9,754.51",-1.3084
184.40002,0.30734,"9,750.66",-1.30552
184.6,0.30766,"9,746.01",-1.29896
184.8,0.308,"9,742.25",-1.30498
185.00002,0.30833,"9,738.99",-1.29686
185.20002,0.30866,"9,735.31",-1.30076
185.40002,0.309,"9,730.79",-1.31401
185.6,0.30934,"9,726.81",-1.28714
185.8,0.30966,"9,721.86",-1.31214
186.00002,0.31,"9,718.70",-1.29197
186.20002,0.31033,"9,714.40",-1.30008
186.40002,0.31067,"9,710.08",-1.3054
186.6,0.311,"9,706.28",-1.28641
186.8,0.31133,"9,701.90",-1.31017
187.00002,0.31166,"9,697.92",-1.30189
187.20002,0.312,"9,694.40",-1.30012
187.40002,0.31233,"9,689.47",-1.29082
187.6,0.31266,"9,684.86",-1.30501
187.8,0.313,"9,681.57",-1.29733
188.00002,0.31333,"9,675.71",-1.29962
188.20002,0.31367,"9,672.64",-1.31285
188.40002,0.314,"9,668.47",-1.30489
188.6,0.31433,"9,662.76",-1.31168
188.8,0.31466,"9,659.23",-1.30194
189.00002,0.315,"9,654.96",-1.29103
189.20002,0.31533,"9,650.30",-1.30454
189.40002,0.31567,"9,647.14",-1.29875
189.6,0.316,"9,641.92",-1.2946
189.8,0.31633,"9,636.59",-1.31
190.00002,0.31667,"9,633.09",-1.29396
190.20002,0.317,"9,628.48",-1.30588
190.40002,0.31733,"9,624.52",-1.30532
190.6,0.31767,"9,619.87",-1.30227
190.8,0.318,"9,614.02",-1.30069
191.00002,0.31833,"9,610.03",-1.29524
191.20002,0.31867,"9,606.09",-1.31037
191.40002,0.319,"9,601.13",-1.30361
191.6,0.31933,"9,596.95",-1.30427
191.8,0.31967,"9,592.24",-1.31031
192.00002,0.31999,"9,586.66",-1.29967
192.20002,0.32033,"9,582.69",-1.3054
192.40002,0.32067,"9,578.01",-1.30134
192.6,0.321,"9,573.07",-1.30206
192.8,0.32133,"9,568.64",-1.30128
193.00002,0.32167,"9,563.35",-1.30246
193.20002,0.32199,"9,558.59",-1.3033
193.40002,0.32234,"9,555.29",-1.30509
193.6,0.32267,"9,549.83",-1.30103
193.8,0.323,"9,544.38",-1.30538
194.00002,0.32333,"9,540.72",-1.30518
194.20002,0.32366,"9,534.89",-1.30122
194.40002,0.324,"9,530.29",-1.30308
194.6,0.32433,"9,526.44",-1.30184
194.8,0.32467,"9,520.78",-1.30164
195.00002,0.325,"9,515.20",-1.30324
195.20002,0.32533,"9,511.24",-1.29804
195.40002,0.32566,"9,505.47",-1.30336
195.6,0.326,"9,501.90",-1.30861
195.8,0.32633,"9,496.68",-1.29176
196.00002,0.32666,"9,491.12",-1.30662
196.20002,0.327,"9,486.96",-1.29795
196.40002,0.32733,"9,481.09",-1.30147
196.6,0.32766,"9,475.78",-1.3045
196.8,0.328,"9,472.37",-1.30108
197.00002,0.32833,"9,466.07",-1.30983
197.20002,0.32866,"9,460.51",-1.30101
197.40002,0.329,"9,456.44",-1.29883
197.6,0.32933,"9,450.65",-1.30861
197.8,0.32966,"9,446.16",-1.30245
198.00002,0.33,"9,441.46",-1.29834
198.20002,0.33033,"9,435.40",-1.30233
198.40002,0.33066,"9,430.61",-1.30293
198.6,0.331,"9,425.81",-1.30756
198.8,0.33133,"9,420.45",-1.30188
199.00002,0.33167,"9,415.72",-1.30194
199.20002,0.332,"9,410.13",-1.30379
199.40002,0.33233,"9,404.64",-1.30424
199.6,0.33266,"9,400.02",-1.3026
199.8,0.333,"9,394.74",-1.30182
200.00002,0.33333,"9,389.53",-1.30555
200.20002,0.33367,"9,384.70",-1.30256
200.40002,0.33399,"9,378.39",-1.30247
200.6,0.33433,"9,372.90",-1.30345
200.8,0.33467,"9,368.69",-1.30248
201.00002,0.335,"9,363.25",-1.30307
201.20002,0.33533,"9,357.98",-1.30503
201.40002,0.33567,"9,352.52",-1.30562
201.6,0.33599,"9,345.94",-1.30374
201.8,0.33633,"9,341.57",-1.30107
202.00002,0.33667,"9,336.70",-1.30293
202.20002,0.337,"9,331.29",-1.30375
202.40002,0.33734,"9,325.78",-1.30211
202.6,0.33766,"9,319.85",-1.30131
202.8,0.338,"9,314.16",-1.30495
203.00002,0.33834,"9,309.53",-1.30627
203.20002,0.33867,"9,303.83",-1.29995
203.40002,0.339,"9,298.40",-1.30617
203.6,0.33933,"9,293.27",-1.30039
203.8,0.33966,"9,286.76",-1.30127
204.00002,0.34,"9,281.55",-1.30635
204.20002,0.34033,"9,276.71",-1.30297
204.40002,0.34067,"9,270.91",-1.30198
204.6,0.341,"9,265.85",-1.30632
204.8,0.34133,"9,260.10",-1.30283
205.00002,0.34166,"9,254.05",-1.30127
205.20002,0.342,"9,249.21",-1.30815
205.40002,0.34233,"9,243.17",-1.30198
205.6,0.34266,"9,236.76",-1.30236
205.8,0.343,"9,231.60",-1.30414
206.00002,0.34333,"9,226.48",-1.30114
206.20002,0.34366,"9,220.93",-1.30351
206.40002,0.344,"9,216.02",-1.30329
206.6,0.34433,"9,209.25",-1.30266
206.8,0.34466,"9,203.16",-1.30726
207.00002,0.345,"9,197.95",-1.30532
207.20002,0.34533,"9,192.26",-1.30444
207.40002,0.34567,"9,186.87",-1.30386
207.6,0.346,"9,181.26",-1.3028
207.8,0.34633,"9,174.67",-1.30508
208.00002,0.34666,"9,169.35",-1.3004
208.20002,0.347,"9,163.62",-1.30466
208.40002,0.34733,"9,158.16",-1.30414
208.6,0.34767,"9,152.64",-1.29886
208.8,0.348,"9,146.09",-1.30732
209.00002,0.34833,"9,140.06",-1.30612
209.20002,0.34866,"9,135.18",-1.30222
209.40002,0.349,"9,128.82",-1.30557
209.6,0.34933,"9,123.59",-1.30195
209.8,0.34967,"9,117.99",-1.2998
210.00002,0.35,"9,111.21",-1.30561
210.20002,0.35033,"9,105.32",-1.30422
210.40002,0.35067,"9,099.82",-1.30077
210.6,0.351,"9,093.83",-1.30405
210.8,0.35133,"9,087.85",-1.30885
211.00002,0.35167,"9,082.22",-1.30199
211.20002,0.352,"9,075.79",-1.3057
211.40002,0.35233,"9,070.71",-1.30376
211.6,0.35267,"9,064.60",-1.30319
211.8,0.353,"9,058.03",-1.30522
212.00002,0.35333,"9,051.73",-1.30262
212.20002,0.35366,"9,045.52",-1.30489
212.40002,0.35399,"9,039.75",-1.30507
212.6,0.35433,"9,034.81",-1.3042
212.8,0.35467,"9,028.72",-1.30273
213.00002,0.355,"9,021.87",-1.30224
213.20002,0.35533,"9,016.16",-1.31031
213.40002,0.35566,"9,009.66",-1.30068
213.6,0.356,"9,003.99",-1.29789
213.8,0.35634,"8,998.59",-1.30784
214.00002,0.35667,"8,991.43",-1.30128
214.20002,0.357,"8,985.56",-1.3039
214.40002,0.35733,"8,979.33",-1.30484
214.6,0.35766,"8,973.12",-1.30382
214.8,0.358,"8,967.97",-1.30331
215.00002,0.35834,"8,961.16",-1.30268
215.20002,0.35866,"8,954.19",-1.30566
215.40002,0.359,"8,949.40",-1.30364
215.6,0.35933,"8,942.27",-1.30024
215.8,0.35966,"8,936.30",-1.30821
216.00002,0.36,"8,931.01",-1.30051
216.20002,0.36033,"8,923.12",-1.30321
216.40002,0.36066,"8,916.99",-1.30621
216.6,0.361,"8,911.64",-1.30084
216.8,0.36133,"8,904.68",-1.3064
217.00002,0.36167,"8,899.00",-1.30386
217.20002,0.362,"8,892.73",-1.30808
217.40002,0.36233,"8,885.52",-1.30073
217.6,0.36266,"8,879.90",-1.30359
217.8,0.363,"8,873.86",-1.30926
218.00002,0.36333,"8,867.31",-1.29805
218.20002,0.36367,"8,860.83",-1.3082
218.40002,0.364,"8,854.37",-1.30138
218.6,0.36433,"8,847.83",-1.30216
218.8,0.36467,"8,842.57",-1.3033
219.00002,0.365,"8,835.43",-1.30684
219.20002,0.36533,"8,829.10",-1.30394
219.40002,0.36567,"8,822.84",-1.30448
219.6,0.366,"8,815.26",-1.3035
219.8,0.36633,"8,809.24",-1.30554
220.00002,0.36667,"8,804.15",-1.30752
220.20002,0.367,"8,797.36",-1.30161
220.40002,0.36733,"8,790.10",-1.30701
220.6,0.36767,"8,784.28",-1.30649
220.8,0.368,"8,776.96",-1.30322
221.00002,0.36833,"8,770.70",-1.30266
221.20002,0.36867,"8,764.61",-1.30575
221.40002,0.369,"8,757.86",-1.30213
221.6,0.36933,"8,751.48",-1.30385
221.8,0.36966,"8,744.57",-1.30718
222.00002,0.37,"8,737.98",-1.30032
222.20002,0.37033,"8,732.34",-1.30067
222.40002,0.37067,"8,724.74",-1.31135
222.6,0.371,"8,717.66",-1.29968
222.8,0.37134,"8,711.84",-1.30219
223.00002,0.37166,"8,704.97",-1.31238
223.20002,0.372,"8,698.72",-1.30006
223.40002,0.37234,"8,692.25",-1.30387
223.6,0.37266,"8,684.14",-1.30837
223.8,0.37299,"8,677.96",-1.30104
224.00002,0.37333,"8,672.01",-1.30778
224.20002,0.37366,"8,665.05",-1.30219
224.40002,0.374,"8,659.44",-1.30615
224.6,0.37434,"8,651.64",-1.30298
224.8,0.37466,"8,644.15",-1.3059
225.00002,0.375,"8,638.31",-1.30596
225.20002,0.37533,"8,631.22",-1.30351
225.40002,0.37566,"8,624.77",-1.30613
225.6,0.376,"8,618.67",-1.3089
225.80002,0.37633,"8,611.01",-1.30256
226.00002,0.37666,"8,603.94",-1.30487
226.20002,0.377,"8,597.30",-1.30466
226.40002,0.37733,"8,590.42",-1.30709
226.6,0.37767,"8,583.68",-1.30703
226.80002,0.378,"8,576.67",-1.30469
227.00002,0.37833,"8,569.34",-1.30544
227.20002,0.37866,"8,563.15",-1.30561
227.40002,0.379,"8,556.22",-1.30642
227.6,0.37933,"8,549.08",-1.3019
227.80002,0.37967,"8,542.33",-1.30211
228.00002,0.38,"8,535.04",-1.30521
228.20002,0.38033,"8,527.59",-1.30546
228.40002,0.38067,"8,521.69",-1.30191
228.6,0.381,"8,514.36",-1.30633
228.80002,0.38133,"8,506.28",-1.3044
229.00002,0.38166,"8,500.08",-1.30245
229.20002,0.382,"8,492.86",-1.31122
229.40002,0.38233,"8,485.91",-1.30299
229.6,0.38267,"8,480.12",-1.30371
229.80002,0.383,"8,472.08",-1.31085
230.00002,0.38333,"8,464.44",-1.29454
230.20002,0.38367,"8,457.69",-1.30811
230.40002,0.384,"8,450.25",-1.30138
230.6,0.38433,"8,443.37",-1.30769
230.80002,0.38467,"8,436.33",-1.3021
231.00002,0.385,"8,428.22",-1.30464
231.20002,0.38533,"8,421.99",-1.30434
231.40002,0.38567,"8,414.38",-1.30365
231.6,0.386,"8,406.96",-1.30864
231.80002,0.38634,"8,400.60",-1.30061
232.00002,0.38667,"8,392.46",-1.30934
232.20002,0.387,"8,385.13",-1.30525
232.40002,0.38733,"8,378.56",-1.30152
232.6,0.38766,"8,370.55",-1.31041
232.80002,0.388,"8,364.16",-1.29624
233.00002,0.38834,"8,356.74",-1.31075
233.20002,0.38866,"8,348.32",-1.30012
233.40002,0.389,"8,341.66",-1.30429
233.6,0.38933,"8,334.79",-1.30934
233.80002,0.38967,"8,326.84",-1.30298
234.00002,0.39,"8,319.44",-1.30771
234.20002,0.39033,"8,311.92",-1.30862
234.40002,0.39066,"8,304.00",-1.30425
234.6,0.391,"8,297.69",-1.30524
234.80002,0.39133,"8,290.20",-1.30126
235.00002,0.39167,"8,282.77",-1.30169
235.20002,0.392,"8,275.13",-1.30358
235.40002,0.39233,"8,266.82",-1.30096
235.6,0.39266,"8,259.53",-1.30746
235.80002,0.393,"8,253.13",-1.30525
236.00002,0.39333,"8,245.04",-1.3048
236.20002,0.39367,"8,237.15",-1.30599
236.40002,0.394,"8,229.61",-1.30677
236.6,0.39433,"8,221.44",-1.30386
236.80002,0.39466,"8,214.25",-1.30615
237.00002,0.395,"8,207.10",-1.3062
237.20002,0.39533,"8,199.24",-1.3043
237.40002,0.39567,"8,192.21",-1.30583
237.6,0.396,"8,183.70",-1.30449
237.80002,0.39633,"8,175.46",-1.30616
238.00002,0.39667,"8,169.17",-1.30583
238.20002,0.397,"8,160.92",-1.30519
238.40002,0.39733,"8,151.93",-1.30402
238.6,0.39767,"8,145.28",-1.30517
238.80002,0.398,"8,136.68",-1.30708
239.00002,0.39833,"8,129.04",-1.30253
239.20002,0.39867,"8,122.25",-1.30426
239.40002,0.399,"8,113.61",-1.3062
239.6,0.39933,"8,106.07",-1.30528
239.80002,0.39967,"8,098.76",-1.30293
240.00002,0.4,"8,090.27",-1.30478
240.20002,0.40033,"8,082.73",-1.30554
240.40002,0.40067,"8,074.15",-1.30495
240.6,0.40099,"8,065.87",-1.30602
240.80002,0.40133,"8,058.62",-1.3055
241.00002,0.40166,"8,050.24",-1.30109
241.20002,0.402,"8,042.61",-1.30692
241.40002,0.40234,"8,034.97",-1.3076
241.6,0.40267,"8,025.22",-1.30284
241.80002,0.403,"8,017.46",-1.30581
242.00002,0.40333,"8,010.54",-1.30176
242.20002,0.40367,"8,001.71",-1.30381
242.40002,0.404,"7,993.55",-1.30559
242.6,0.40434,"7,985.92",-1.30384
242.80002,0.40466,"7,977.21",-1.30385
243.00002,0.405,"7,968.72",-1.30399
243.20002,0.40534,"7,960.94",-1.30491
243.40002,0.40566,"7,952.93",-1.3056
243.6,0.406,"7,944.17",-1.30543
243.80002,0.40633,"7,935.66",-1.30282
244.00002,0.40666,"7,927.46",-1.30453
244.20002,0.407,"7,919.91",-1.30685
244.40002,0.40733,"7,911.19",-1.30469
244.6,0.40767,"7,902.22",-1.3021
244.80002,0.408,"7,894.18",-1.30737
245.00002,0.40833,"7,885.09",-1.30571
245.20002,0.40866,"7,877.17",-1.30607
245.40002,0.409,"7,869.82",-1.3063
245.6,0.40933,"7,860.27",-1.30503
245.80002,0.40966,"7,851.82",-1.30578
246.00002,0.41,"7,843.78",-1.30324
246.20002,0.41033,"7,834.01",-1.30398
246.40002,0.41067,"7,826.52",-1.30763
246.6,0.411,"7,818.22",-1.30373
246.80002,0.41133,"7,808.18",-1.30643
247.00002,0.41166,"7,800.13",-1.30652
247.20002,0.412,"7,791.21",-1.30516
247.40002,0.41233,"7,782.82",-1.30266
247.6,0.41267,"7,774.67",-1.30564
247.80002,0.413,"7,765.57",-1.30262
248.00002,0.41333,"7,755.85",-1.30702
248.20002,0.41367,"7,747.65",-1.30282
248.40002,0.414,"7,738.49",-1.30329
248.6,0.41433,"7,730.32",-1.30765
248.80002,0.41467,"7,721.55",-1.30346
249.00002,0.415,"7,711.03",-1.30733
249.20002,0.41533,"7,702.79",-1.30511
249.40002,0.41567,"7,694.08",-1.30187
249.6,0.416,"7,685.04",-1.30813
249.80002,0.41633,"7,676.97",-1.30467
250.00002,0.41667,"7,667.07",-1.30451
250.20002,0.41699,"7,657.16",-1.30588
250.40002,0.41733,"7,649.35",-1.30838
250.6,0.41767,"7,639.57",-1.30201
250.80002,0.41799,"7,630.03",-1.30489
251.00002,0.41834,"7,621.19",-1.30569
251.20002,0.41867,"7,611.41",-1.30433
251.40002,0.41899,"7,601.75",-1.30222
251.6,0.41933,"7,593.75",-1.30491
251.80002,0.41967,"7,583.45",-1.30561
252.00002,0.42,"7,573.62",-1.30354
252.20002,0.42033,"7,564.70",-1.30783
252.40002,0.42066,"7,554.41",-1.30504
252.6,0.421,"7,545.57",-1.30552
252.80002,0.42133,"7,536.04",-1.30594
253.00002,0.42167,"7,525.92",-1.30782
253.20002,0.422,"7,516.11",-1.3057
253.40002,0.42233,"7,506.04",-1.30544
253.6,0.42266,"7,495.88",-1.30424
253.80002,0.423,"7,487.48",-1.303
254.00002,0.42334,"7,477.21",-1.31113
254.20002,0.42367,"7,466.42",-1.30386
254.40002,0.424,"7,456.94",-1.30337
254.6,0.42433,"7,445.96",-1.30609
254.80002,0.42466,"7,435.65",-1.30422
255.00002,0.425,"7,426.54",-1.30601
255.20002,0.42533,"7,415.31",-1.30555
255.40002,0.42566,"7,403.89",-1.30298
255.6,0.426,"7,393.00",-1.30712
255.80002,0.42633,"7,380.47",-1.30299
256,0.42666,"7,368.86",-1.30672
256.13602,0.42689,"7,285.74",-1.30475
256.14002,0.42691,"6,910.89",-1.30483
256.14402,0.42694,"6,247.27",-1.30414
256.14802,0.42697,"5,466.24",-1.30673
256.15202,0.427,"4,636.87",-1.31707
256.15402,0.42702,"4,217.97",-1.32309