File: Unfinished Projects/Stress and Strain Analysis with Matplotlib/Group 1 Aluminum.csv
Strain : Axial Gauge Length (Strain Source),2,in,
Strain : Time at Removal (Strain Source),,ms,
,,,
Time,Extension,Load,Strain 1
(sec),(in),(lbf),(%)
0,0,-0.07301,-0.00001
0.2,0.00018,0.13564,0.00004
0.4,0.00062,0.17409,0.00005
0.6,0.00099,0.25899,0.00003
0.8,0.00133,0.22198,0.00008
1,0.00166,0.09281,0.00003
1.2,0.002,0.17864,0.00014
1.4,0.00233,0.23563,0.00015
1.6,0.00267,0.31213,0.00018
1.8,0.003,0.15052,0.00012
2,0.00333,0.17844,0.00013
2.2,0.00367,0.24205,0.00011
2.4,0.004,0.33404,0.00001
2.6,0.00433,0.35704,0.00007
2.8,0.00467,0.50111,0.00006
3,0.005,4.00119,0.00019
3.2,0.00533,9.52665,0.00041
3.4,0.00567,17.5279,0.00079
3.6,0.006,28.54271,0.00171
3.8,0.00633,39.30875,0.00256
4,0.00666,50.23676,0.00342
4.2,0.007,61.32916,0.00424
4.4,0.00733,72.71928,0.00506
4.6,0.00766,85.16654,0.00594
4.8,0.008,97.42575,0.00685
5,0.00833,109.88769,0.0078
5.2,0.00866,122.86754,0.00872
5.4,0.00899,136.96525,0.00974
5.6,0.00933,152.96346,0.01044
5.8,0.00967,169.65909,0.01134
6,0.01,186.502,0.01233
6.2,0.01033,203.6713,0.01352
6.4,0.01066,221.23175,0.01471
6.6,0.011,239.26348,0.01588
6.8,0.01133,257.65238,0.01711
7,0.01167,276.0205,0.01837
7.2,0.012,295.17028,0.01969
7.4,0.01233,314.91558,0.02095
7.6,0.01266,335.43321,0.02209
7.8,0.013,355.8367,0.02346
8,0.01333,376.7441,0.02478
8.2,0.01366,397.64606,0.02609
8.4,0.014,418.5983,0.02743
8.6,0.01433,440.35579,0.02865
8.8,0.01466,462.12315,0.02987
9,0.015,483.8326,0.03121
9.2,0.01533,505.52602,0.03236
9.4,0.01566,527.37499,0.03355
9.6,0.01599,549.416,0.0347
9.8,0.01633,572.42179,0.03589
10,0.01667,595.06378,0.03704
10.2,0.017,618.04833,0.0382
10.4,0.01733,641.13812,0.0393
10.6,0.01766,664.80576,0.04052
10.8,0.018,688.90864,0.04182
11,0.01833,713.81626,0.04304
11.2,0.01866,738.00348,0.04434
11.4,0.019,763.16594,0.04561
11.6,0.01933,788.57101,0.04689
11.8,0.01966,814.17382,0.04831
12,0.02,840.52207,0.04958
12.2,0.02033,866.35685,0.05091
12.4,0.02066,892.74471,0.05228
12.6,0.021,919.38851,0.05369
12.8,0.02133,945.90308,0.0551
13,0.02166,973.32447,0.0565
13.2,0.022,"1,001.19",0.05788
13.4,0.02233,"1,028.59",0.0592
13.6,0.02266,"1,056.67",0.06053
13.8,0.023,"1,085.50",0.06189
14,0.02333,"1,113.86",0.0633
14.2,0.02366,"1,142.72",0.06471
14.4,0.024,"1,171.78",0.06614
14.6,0.02433,"1,200.59",0.06763
14.8,0.02466,"1,230.26",0.06902
15,0.025,"1,260.36",0.07047
15.2,0.02533,"1,290.75",0.07185
15.4,0.02567,"1,321.29",0.07337
15.6,0.02599,"1,351.29",0.07481
15.8,0.02633,"1,382.19",0.07633
16,0.02666,"1,414.16",0.07803
16.2,0.02699,"1,446.95",0.07988
16.4,0.02733,"1,480.28",0.08184
16.6,0.02767,"1,513.21",0.08396
16.8,0.02799,"1,546.93",0.08604
17,0.02833,"1,581.06",0.08817
17.2,0.02866,"1,615.38",0.0903
17.4,0.029,"1,650.60",0.09228
17.6,0.02933,"1,685.99",0.0944
17.8,0.02966,"1,721.61",0.09649
18,0.02999,"1,757.23",0.09845
18.2,0.03033,"1,794.66",0.10063
18.4,0.03066,"1,831.65",0.10277
18.6,0.031,"1,868.84",0.1048
18.8,0.03133,"1,906.27",0.10693
19,0.03166,"1,943.71",0.10906
19.2,0.03199,"1,981.87",0.11113
19.4,0.03233,"2,020.59",0.11329
19.6,0.03267,"2,059.32",0.1153
19.8,0.03299,"2,097.59",0.11735
20,0.03333,"2,136.21",0.11936
20.2,0.03366,"2,175.41",0.12149
20.4,0.034,"2,215.82",0.12373
20.6,0.03433,"2,256.10",0.12577
20.8,0.03466,"2,295.58",0.12789
21,0.03499,"2,336.46",0.12992
21.2,0.03533,"2,377.20",0.13208
21.4,0.03566,"2,418.14",0.13407
21.6,0.036,"2,460.02",0.13621
21.8,0.03633,"2,501.00",0.13832
22,0.03666,"2,542.45",0.1404
22.2,0.03699,"2,584.12",0.14255
22.4,0.03733,"2,626.47",0.14477
22.6,0.03766,"2,668.83",0.14694
22.8,0.038,"2,711.23",0.14916
23,0.03833,"2,753.54",0.15133
23.2,0.03866,"2,795.77",0.15343
23.4,0.03899,"2,838.50",0.15557
23.6,0.03933,"2,881.88",0.15777
23.8,0.03967,"2,925.41",0.16001
24,0.04,"2,968.16",0.16214
24.2,0.04033,"3,011.68",0.16444
24.4,0.04066,"3,055.21",0.16667
24.6,0.041,"3,098.85",0.16894
24.8,0.04133,"3,142.80",0.17118
25,0.04167,"3,186.99",0.17341
25.2,0.04199,"3,230.76",0.17558
25.4,0.04233,"3,274.84",0.17775
25.6,0.04266,"3,319.80",0.18001
25.8,0.043,"3,364.08",0.1823
26,0.04333,"3,408.51",0.18453
26.2,0.04366,"3,453.25",0.18677
26.4,0.04399,"3,498.17",0.18907
26.6,0.04433,"3,543.54",0.19134
26.8,0.04467,"3,589.24",0.1936
27,0.045,"3,634.32",0.19583
27.2,0.04533,"3,679.07",0.19803
27.4,0.04566,"3,724.94",0.20034
27.6,0.04599,"3,770.42",0.20249
27.8,0.04633,"3,816.85",0.20487
28,0.04666,"3,863.03",0.20719
28.2,0.047,"3,908.89",0.20935
28.4,0.04733,"3,955.01",0.21179
28.6,0.04766,"4,000.90",0.21411
28.8,0.04799,"4,047.92",0.21644
29,0.04833,"4,095.59",0.21879
29.2,0.04866,"4,140.99",0.22105
29.4,0.04899,"4,187.89",0.22335
29.6,0.04933,"4,235.14",0.22564
29.8,0.04966,"4,281.30",0.22795
30,0.05,"4,329.70",0.23038
30.2,0.05033,"4,377.05",0.23271
30.4,0.05066,"4,423.01",0.23498
30.6,0.051,"4,471.11",0.23735
30.8,0.05133,"4,518.96",0.23974
31,0.05166,"4,566.43",0.24206
31.2,0.052,"4,614.45",0.24448
31.4,0.05233,"4,661.69",0.24679
31.6,0.05266,"4,709.34",0.24912
31.8,0.053,"4,757.85",0.25164
32,0.05333,"4,805.97",0.25397
32.2,0.05366,"4,854.63",0.2563
32.4,0.054,"4,902.79",0.25862
32.6,0.05432,"4,950.66",0.26094
32.8,0.05466,"4,999.76",0.26329
33,0.055,"5,049.35",0.26579
33.2,0.05533,"5,097.91",0.2682
33.4,0.05567,"5,147.09",0.2707
33.6,0.056,"5,195.50",0.2729
33.8,0.05633,"5,243.82",0.27524
34,0.05666,"5,293.47",0.27766
34.2,0.057,"5,342.49",0.27998
34.4,0.05733,"5,391.60",0.28231
34.6,0.05767,"5,440.80",0.28467
34.8,0.05799,"5,489.94",0.28713
35,0.05833,"5,539.11",0.28951
35.2,0.05866,"5,589.33",0.29203
35.4,0.059,"5,638.73",0.29451
35.6,0.05933,"5,687.75",0.297
35.8,0.05966,"5,737.40",0.29938
36,0.05999,"5,786.74",0.30176
36.2,0.06033,"5,836.94",0.30417
36.4,0.06067,"5,887.05",0.30662
36.6,0.06099,"5,936.23",0.30907
36.8,0.06133,"5,986.31",0.31156
37,0.06166,"6,035.83",0.31405
37.2,0.06199,"6,085.76",0.31651
37.4,0.06233,"6,136.76",0.31903
37.6,0.06266,"6,186.43",0.32142
37.8,0.06299,"6,235.07",0.32385
38,0.06333,"6,286.03",0.3264
38.2,0.06366,"6,336.10",0.3289
38.4,0.064,"6,386.79",0.33147
38.6,0.06433,"6,436.90",0.33409
38.8,0.06466,"6,485.77",0.33655
39,0.06499,"6,536.30",0.33901
39.2,0.06533,"6,586.50",0.34146
39.4,0.06566,"6,635.74",0.34391
39.6,0.066,"6,686.58",0.3464
39.8,0.06633,"6,736.18",0.34897
40,0.06666,"6,785.10",0.35149
40.2,0.06699,"6,835.48",0.35414
40.4,0.06733,"6,885.29",0.35666
40.6,0.06766,"6,936.07",0.35925
40.8,0.068,"6,986.14",0.36181
41,0.06833,"7,035.46",0.36429
41.2,0.06866,"7,085.25",0.3668
41.4,0.069,"7,135.56",0.36938
41.6,0.06933,"7,185.20",0.37188
41.8,0.06966,"7,235.02",0.37452
42,0.07,"7,285.09",0.37706
42.2,0.07033,"7,334.04",0.37966
42.4,0.07066,"7,384.26",0.38223
42.6,0.071,"7,434.98",0.38486
42.8,0.07133,"7,484.91",0.3875
43,0.07166,"7,535.12",0.39019
43.2,0.07199,"7,584.56",0.39292
43.4,0.07233,"7,634.13",0.3955
43.6,0.07267,"7,684.97",0.39825
43.8,0.073,"7,734.52",0.40086
44,0.07333,"7,783.06",0.40346
44.2,0.07367,"7,833.05",0.40632
44.4,0.074,"7,882.06",0.40894
44.6,0.07432,"7,930.82",0.41189
44.8,0.07466,"7,981.43",0.41483
45,0.075,"8,029.93",0.41783
45.2,0.07533,"8,078.16",0.42071
45.4,0.07566,"8,127.31",0.42369
45.6,0.07599,"8,175.34",0.42678
45.8,0.07633,"8,224.24",0.42988
46,0.07666,"8,272.03",0.43317
46.2,0.077,"8,318.91",0.43641
46.4,0.07733,"8,366.38",0.43989
46.6,0.07766,"8,412.50",0.44337
46.8,0.07799,"8,459.00",0.44701
47,0.07833,"8,506.32",0.45079
47.2,0.07866,"8,551.05",0.45466
47.4,0.07899,"8,595.61",0.45858
47.6,0.07933,"8,641.67",0.4628
47.8,0.07966,"8,685.20",0.46704
48,0.08,"8,728.45",0.47152
48.2,0.08033,"8,771.12",0.47619
48.4,0.08066,"8,812.18",0.48091
48.6,0.08099,"8,852.74",0.48603
48.8,0.08133,"8,893.35",0.49122
49,0.08166,"8,931.90",0.49679
49.2,0.082,"8,969.56",0.50269
49.4,0.08233,"9,005.36",0.50861
49.6,0.08266,"9,039.87",0.51532
49.8,0.083,"9,073.57",0.52227
50,0.08333,"9,103.75",0.52967
50.2,0.08366,"9,132.70",0.5376
50.4,0.084,"9,159.24",0.54622
50.6,0.08433,"9,181.84",0.55527
50.8,0.08466,"9,202.24",0.56511
51,0.085,"9,221.71",0.57564
51.2,0.08533,"9,236.52",0.5867
51.4,0.08567,"9,250.40",0.59818
51.6,0.086,"9,261.83",0.61039
51.8,0.08633,"9,270.75",0.62275
52,0.08666,"9,280.24",0.63565
52.2,0.087,"9,288.32",0.64884
52.4,0.08733,"9,294.31",0.66216
52.6,0.08767,"9,301.12",0.67565
52.8,0.088,"9,306.30",0.68954
53,0.08833,"9,311.45",0.7033
53.2,0.08867,"9,317.57",0.71728
53.4,0.089,"9,321.73",0.73158
53.6,0.08933,"9,325.82",0.7457
53.8,0.08966,"9,329.49",0.75997
54,0.08999,"9,332.85",0.7743
54.2,0.09033,"9,337.33",0.78888
54.4,0.09067,"9,341.40",0.8033
54.6,0.091,"9,344.38",0.8177
54.8,0.09133,"9,347.94",0.83225
55,0.09167,"9,351.19",0.84689
55.2,0.092,"9,354.36",0.86135
55.4,0.09233,"9,357.94",0.87613
55.6,0.09267,"9,361.26",0.89089
55.8,0.093,"9,363.36",0.90547
56,0.09333,"9,366.66",0.92003
56.2,0.09366,"9,369.44",0.935
56.4,0.094,"9,372.40",0.9496
56.6,0.09434,"9,376.57",0.96422
56.8,0.09467,"9,378.30",0.97901
57,0.09499,"9,380.88",0.99363
57.2,0.09533,"9,384.35",1.00847
57.4,0.09567,"9,387.40",1.02322
57.6,0.096,"9,390.21",1.03805
57.8,0.09634,"9,393.39",1.05269
58,0.09666,"9,395.23",1.06751
58.2,0.097,"9,398.38",1.08228
58.4,0.09733,"9,401.77",1.09723
58.6,0.09766,"9,404.49",1.11188
58.8,0.098,"9,407.07",1.12678
59,0.09833,"9,409.16",1.14145
59.2,0.09866,"9,411.81",1.15627
59.4,0.099,"9,415.17",1.17105
59.6,0.09933,"9,417.49",1.18578
59.8,0.09966,"9,420.67",1.20046
60,0.1,"9,423.72",1.21524
60.2,0.10033,"9,425.50",1.22996
60.4,0.10066,"9,428.49",1.24464
60.6,0.101,"9,432.28",1.25949
60.8,0.10133,"9,434.44",1.27414
61,0.10167,"9,437.13",1.28884
61.2,0.102,"9,440.08",1.30355
61.4,0.10233,"9,441.94",1.31826
61.6,0.10266,"9,445.78",1.33277
61.8,0.103,"9,449.08",1.34775
62,0.10333,"9,450.73",1.36219
62.2,0.10366,"9,453.33",1.37684
62.4,0.104,"9,455.90",1.39159
62.6,0.10433,"9,459.20",1.4063
62.8,0.10467,"9,462.72",1.42106
63,0.105,"9,464.79",1.4358
63.2,0.10533,"9,467.00",1.45043
63.4,0.10567,"9,469.98",1.46526
63.6,0.10599,"9,472.27",1.47989
63.8,0.10633,"9,475.28",1.4946
64,0.10667,"9,478.75",1.50934
64.2,0.107,"9,480.28",1.52398
64.4,0.10733,"9,483.21",1.53859
64.60001,0.10766,"9,485.73",1.55324
64.8,0.10799,"9,488.46",1.56781
65,0.10833,"9,492.42",1.58246
65.2,0.10867,"9,494.68",1.59714
65.4,0.10899,"9,496.62",1.61163
65.60001,0.10933,"9,500.43",1.62633
65.8,0.10966,"9,502.39",1.641
66,0.10999,"9,505.17",1.65565
66.20001,0.11033,"9,508.53",1.67037
66.4,0.11066,"9,510.03",1.68488
66.60001,0.11099,"9,512.78",1.69951
66.8,0.11133,"9,515.79",1.71424
67,0.11166,"9,518.23",1.72883
67.20001,0.112,"9,520.95",1.74346
67.4,0.11233,"9,523.42",1.758
67.60001,0.11266,"9,525.52",1.77258
67.8,0.113,"9,528.37",1.78704
68,0.11333,"9,531.68",1.80174
68.20001,0.11366,"9,534.40",1.81617
68.4,0.114,"9,537.29",1.8309
68.60001,0.11433,"9,539.48",1.84548
68.8,0.11466,"9,541.71",1.86011
69,0.115,"9,544.71",1.87478
69.20001,0.11533,"9,547.18",1.8895
69.4,0.11566,"9,549.80",1.90381
69.60001,0.116,"9,552.17",1.91856
69.8,0.11633,"9,554.27",1.93313
70,0.11666,"9,557.28",1.94761
70.20001,0.117,"9,560.96",1.96217
70.4,0.11733,"9,562.82",1.97685
70.60001,0.11767,"9,564.90",1.99146
70.8,0.118,"9,568.01",2.00619
71,0.11833,"9,570.01",2.02081
71.20001,0.11867,"9,572.81",2.03537
71.4,0.119,"9,575.97",2.04988
71.60001,0.11933,"9,577.18",2.06428
71.8,0.11966,"9,580.14",2.07894
72,0.12,"9,582.42",2.09355
72.20001,0.12033,"9,585.30",2.10802
72.4,0.12067,"9,588.92",2.12266
72.60001,0.121,"9,590.10",2.13712
72.8,0.12133,"9,592.69",2.15171
73,0.12167,"9,595.85",2.16666
73.20001,0.12199,"9,597.25",2.18116
73.4,0.12233,"9,600.75",2.19578
73.60001,0.12267,"9,603.66",2.21046
73.8,0.12299,"9,603.91",2.22508
74,0.12333,"9,606.82",2.23953
74.20001,0.12367,"9,609.77",2.25426
74.4,0.12399,"9,611.87",2.26862
74.60001,0.12433,"9,615.27",2.28328
74.8,0.12467,"9,616.70",2.29783
75,0.125,"9,618.80",2.31242
75.20001,0.12533,"9,621.87",2.32707
75.4,0.12566,"9,624.24",2.34173
75.60001,0.126,"9,626.95",2.35617
75.8,0.12634,"9,629.76",2.37078
76,0.12666,"9,630.96",2.38536
76.20001,0.12699,"9,632.96",2.39993
76.4,0.12733,"9,636.30",2.41456
76.60001,0.12766,"9,638.44",2.42926
76.8,0.128,"9,640.85",2.44361
77,0.12833,"9,642.90",2.45821
77.20001,0.12866,"9,644.50",2.47298
77.4,0.129,"9,647.68",2.48747
77.60001,0.12933,"9,650.49",2.5022
77.8,0.12967,"9,651.87",2.51681
78,0.13,"9,654.09",2.53147
78.20001,0.13033,"9,656.38",2.54602
78.4,0.13066,"9,657.74",2.56061
78.60001,0.131,"9,661.80",2.57532
78.8,0.13133,"9,663.60",2.59002
79,0.13166,"9,664.85",2.60447
79.20001,0.132,"9,667.80",2.61929
79.4,0.13233,"9,669.57",2.63396
79.60001,0.13266,"9,671.67",2.6484
79.8,0.133,"9,675.37",2.66324
80,0.13333,"9,676.17",2.67785
80.20001,0.13366,"9,678.01",2.6922
80.4,0.134,"9,680.83",2.70688
80.60001,0.13433,"9,682.48",2.72152
80.8,0.13467,"9,685.59",2.73627
81.00001,0.135,"9,687.99",2.75089
81.20001,0.13533,"9,688.42",2.76553
81.4,0.13566,"9,691.42",2.78016
81.60001,0.136,"9,692.75",2.79478
81.8,0.13633,"9,694.84",2.80917
82.00001,0.13667,"9,698.57",2.82391
82.20001,0.137,"9,699.04",2.83839
82.4,0.13733,"9,701.07",2.85299
82.60001,0.13767,"9,703.81",2.86778
82.8,0.138,"9,705.65",2.88249
83.00001,0.13833,"9,708.07",2.89703
83.20001,0.13867,"9,710.03",2.9117
83.4,0.13899,"9,711.22",2.92623
83.60001,0.13933,"9,713.83",2.94078
83.8,0.13966,"9,716.27",2.95569
84.00001,0.13999,"9,717.65",2.97044
84.20001,0.14033,"9,719.88",2.98514
84.4,0.14066,"9,721.22",2.99978
84.60001,0.14099,"9,723.16",3.01434
84.8,0.14133,"9,725.72",3.02912
85.00001,0.14167,"9,727.75",3.04385
85.20001,0.142,"9,729.63",3.05831
85.4,0.14233,"9,731.57",3.07325
85.60001,0.14266,"9,732.71",3.08768
85.8,0.14299,"9,734.34",3.10232
86.00001,0.14333,"9,737.46",3.11706
86.20001,0.14366,"9,739.05",3.13193
86.4,0.144,"9,740.07",3.1462
86.60001,0.14433,"9,742.19",3.16113
86.8,0.14466,"9,743.55",3.17569
87.00001,0.145,"9,745.75",3.19055
87.20001,0.14533,"9,748.42",3.20495
87.4,0.14566,"9,749.72",3.21976
87.60001,0.146,"9,752.08",3.23445
87.8,0.14633,"9,753.54",3.24926
88.00001,0.14666,"9,754.89",3.26372
88.20001,0.147,"9,757.92",3.27872
88.4,0.14733,"9,759.13",3.29336
88.60001,0.14766,"9,759.82",3.30793
88.8,0.148,"9,762.37",3.32278
89.00001,0.14833,"9,763.81",3.33773
89.20001,0.14866,"9,765.48",3.35221
89.4,0.149,"9,768.50",3.36691
89.60001,0.14933,"9,768.91",3.38176
89.8,0.14966,"9,770.76",3.39636
90.00001,0.15,"9,772.81",3.41119
90.20001,0.15033,"9,774.69",3.42608
90.4,0.15066,"9,776.36",3.441
90.60001,0.151,"9,777.40",3.45557
90.8,0.15133,"9,778.62",3.4703
91.00001,0.15167,"9,780.72",3.48507
91.20001,0.152,"9,782.16",3.49996
91.4,0.15233,"9,784.02",3.51442
91.60001,0.15267,"9,785.97",3.52932
91.8,0.153,"9,786.73",3.54412
92.00001,0.15333,"9,788.22",3.55893
92.20001,0.15367,"9,791.10",3.57379
92.4,0.154,"9,792.04",3.58881
92.60001,0.15433,"9,793.77",3.60332
92.8,0.15467,"9,795.60",3.61828
93.00001,0.155,"9,796.04",3.63309
93.20001,0.15533,"9,797.40",3.64808
93.4,0.15567,"9,800.22",3.6629
93.60001,0.156,"9,801.50",3.6777
93.8,0.15633,"9,802.86",3.69254
94.00001,0.15666,"9,804.15",3.70757
94.20001,0.15699,"9,805.12",3.72233
94.4,0.15733,"9,807.35",3.73725
94.60001,0.15767,"9,809.09",3.75231
94.8,0.158,"9,809.99",3.767
95.00001,0.15833,"9,811.79",3.78183
95.20001,0.15866,"9,812.79",3.79683
95.4,0.159,"9,814.47",3.81192
95.60001,0.15933,"9,816.90",3.82671
95.8,0.15966,"9,817.12",3.84153
96.00001,0.16,"9,818.64",3.8564
96.20001,0.16033,"9,821.10",3.8715
96.4,0.16066,"9,820.73",3.88627
96.60001,0.161,"9,822.96",3.90111
96.8,0.16134,"9,824.99",3.91617
97.00001,0.16166,"9,824.69",3.93087
97.20001,0.162,"9,826.77",3.94574
97.4,0.16233,"9,828.12",3.96073
97.60001,0.16266,"9,829.42",3.97577
97.8,0.163,"9,831.49",3.99047
98.00001,0.16334,"9,832.47",4.00554
98.20001,0.16366,"9,833.12",4.02038
98.4,0.164,"9,834.60",4.03555
98.60001,0.16433,"9,835.59",4.05032
98.8,0.16466,"9,837.31",4.06539
99.00001,0.165,"9,838.82",4.08039
99.20001,0.16533,"9,838.80",4.09522
99.4,0.16566,"9,840.87",4.11009
99.60001,0.166,"9,842.39",4.12534
99.8,0.16633,"9,843.27",4.14047
100.00001,0.16667,"9,844.98",4.15525
100.20001,0.167,"9,846.36",4.17043
100.4,0.16733,"9,846.24",4.1855
100.60001,0.16766,"9,848.01",4.20061
100.8,0.168,"9,849.10",4.21551
101.00001,0.16833,"9,849.85",4.23051
101.20001,0.16867,"9,851.82",4.24542
101.4,0.169,"9,852.67",4.26056
101.60001,0.16933,"9,852.95",4.27537
101.8,0.16967,"9,855.49",4.29066
102.00001,0.17,"9,856.22",4.30571
102.20001,0.17033,"9,856.97",4.32062
102.4,0.17067,"9,858.33",4.33567
102.60001,0.17099,"9,858.72",4.3506
102.8,0.17133,"9,860.47",4.36568
103.00001,0.17167,"9,861.91",4.38068
103.20001,0.172,"9,862.97",4.39581
103.4,0.17233,"9,863.59",4.41091
103.60001,0.17266,"9,864.39",4.42601
103.8,0.17299,"9,865.22",4.44093
104.00001,0.17333,"9,867.59",4.45627
104.20001,0.17367,"9,868.39",4.47141
104.4,0.174,"9,868.50",4.48629
104.60001,0.17433,"9,870.46",4.50151
104.8,0.17466,"9,870.55",4.51683
105.00001,0.17499,"9,871.47",4.53183
105.20001,0.17533,"9,873.93",4.547
105.4,0.17567,"9,874.12",4.56209
105.60001,0.176,"9,873.93",4.57729
105.8,0.17633,"9,875.78",4.5924
106.00001,0.17666,"9,876.27",4.60751
106.20001,0.177,"9,877.43",4.62275
106.4,0.17734,"9,879.11",4.63808
106.60001,0.17766,"9,878.81",4.65322
106.8,0.178,"9,879.83",4.66804
107.00001,0.17833,"9,880.91",4.68337
107.20001,0.17866,"9,881.81",4.69857
107.4,0.179,"9,883.37",4.71355
107.60001,0.17933,"9,883.37",4.72876
107.8,0.17966,"9,883.73",4.7438
108.00001,0.18,"9,885.84",4.75907
108.20001,0.18033,"9,886.03",4.77412
108.4,0.18067,"9,887.18",4.78951
108.60001,0.18101,"9,888.72",4.80483
108.8,0.18133,"9,887.56",4.82007
109.00001,0.18166,"9,888.73",4.83494
109.20001,0.182,"9,890.78",4.85029
109.4,0.18233,"9,890.73",4.86552
109.60001,0.18267,"9,891.48",4.88057
109.8,0.183,"9,892.31",4.89572
110.00001,0.18333,"9,892.11",4.91094
110.20001,0.18366,"9,893.48",4.92614
110.4,0.184,"9,895.00",4.94136
110.60001,0.18433,"9,895.46",4.95637
110.8,0.18467,"9,896.22",4.97174
111.00001,0.185,"9,896.46",4.98714
111.20001,0.18533,"9,897.19",5.00218
111.4,0.18567,"9,898.39",5.01754
111.60001,0.186,"9,898.78",5.03289
111.8,0.18633,"9,898.99",5.04812
112.00001,0.18667,"9,900.43",5.06323
112.20001,0.187,"9,900.36",5.07853
112.4,0.18733,"9,901.17",5.09369
112.60001,0.18767,"9,903.24",5.10911
112.8,0.188,"9,902.83",5.12429
113.00001,0.18833,"9,903.09",5.13961
113.20001,0.18867,"9,904.17",5.15506
113.40001,0.189,"9,904.50",5.17029
113.60001,0.18933,"9,905.92",5.18556
113.8,0.18967,"9,906.13",5.20101
114.00001,0.18999,"9,905.59",5.21637
114.20001,0.19033,"9,907.10",5.23168
114.40001,0.19066,"9,907.53",5.24694
114.60001,0.19099,"9,908.06",5.26231
114.8,0.19134,"9,909.96",5.27795
115.00001,0.19167,"9,909.22",5.29327
115.20001,0.19199,"9,909.42",5.3086
115.40001,0.19233,"9,910.53",5.32407
115.60001,0.19266,"9,910.54",5.33934
115.8,0.193,"9,911.15",5.35473
116.00001,0.19334,"9,912.03",5.37002
116.20001,0.19366,"9,911.67",5.38557
116.40001,0.194,"9,912.21",5.40081
116.60001,0.19433,"9,913.08",5.41625
116.8,0.19466,"9,913.51",5.43152
117.00001,0.195,"9,914.86",5.44716
117.20001,0.19533,"9,914.45",5.46267
117.40001,0.19566,"9,914.56",5.47804
117.60001,0.196,"9,915.79",5.49349
117.8,0.19633,"9,915.53",5.50906
118.00001,0.19666,"9,916.03",5.52452
118.20001,0.197,"9,916.92",5.5399
118.40001,0.19733,"9,916.37",5.55541
118.60001,0.19766,"9,916.90",5.57081
118.8,0.198,"9,918.33",5.58645
119.00001,0.19833,"9,918.43",5.60188
119.20001,0.19866,"9,918.13",5.61713
119.40001,0.199,"9,918.86",5.63296
119.60001,0.19933,"9,918.97",5.64845
119.8,0.19966,"9,919.59",5.66406
120.00001,0.2,"9,920.05",5.67949
120.20001,0.20033,"9,920.14",5.69518
120.40001,0.20066,"9,920.28",5.71056
120.60001,0.20099,"9,920.25",5.72623
120.8,0.20133,"9,920.55",5.74153
121.00001,0.20167,"9,921.90",5.75736
121.20001,0.202,"9,922.31",5.77299
121.40001,0.20233,"9,921.28",5.78855
121.60001,0.20267,"9,922.19",5.80429
121.8,0.20299,"9,922.02",5.81973
122.00001,0.20333,"9,922.39",5.83541
122.20001,0.20367,"9,923.46",5.85111
122.40001,0.204,"9,922.71",5.86663
122.60001,0.20433,"9,923.08",5.88222
122.8,0.20467,"9,923.35",5.89809
123.00001,0.205,"9,923.22",5.91368
123.20001,0.20533,"9,924.26",5.92918
123.40001,0.20567,"9,924.14",5.94499
123.60001,0.20599,"9,923.37",5.96056
123.8,0.20633,"9,924.34",5.97634
124.00001,0.20666,"9,924.24",5.99196
124.20001,0.207,"9,924.65",6.00758
124.40001,0.20734,"9,925.18",6.02334
124.60001,0.20766,"9,924.33",6.03898
124.8,0.208,"9,924.91",6.05468
125.00001,0.20833,"9,925.43",6.07023
125.20001,0.20866,"9,925.28",6.08614
125.40001,0.209,"9,926.41",6.10182
125.60001,0.20933,"9,925.89",6.11782
125.8,0.20966,"9,924.86",6.13325
126.00001,0.21,"9,926.00",6.14935
126.20001,0.21033,"9,926.04",6.16503
126.40001,0.21066,"9,926.10",6.18065
126.60001,0.211,"9,925.91",6.19629
126.8,0.21133,"9,925.72",6.21228
127.00001,0.21166,"9,925.59",6.22802
127.20001,0.212,"9,926.68",6.24378
127.40001,0.21233,"9,926.39",6.25973
127.60001,0.21267,"9,926.23",6.27551
127.8,0.213,"9,926.41",6.29154
128,0.21333,"9,925.64",6.3072
128.20002,0.21366,"9,925.89",6.32292
128.40001,0.214,"9,926.69",6.33883
128.60001,0.21433,"9,926.30",6.35471
128.8,0.21467,"9,925.90",6.37065
129,0.215,"9,926.33",6.38659
129.20002,0.21533,"9,925.67",6.40237
129.40001,0.21566,"9,926.34",6.41834
129.60001,0.216,"9,926.35",6.43426
129.8,0.21633,"9,925.53",6.45019
130,0.21666,"9,926.09",6.46619
130.20002,0.217,"9,925.56",6.4821
130.40001,0.21733,"9,925.58",6.49793
130.60001,0.21767,"9,926.34",6.51416
130.8,0.218,"9,925.14",6.5299
131,0.21833,"9,924.31",6.5457
131.20002,0.21867,"9,925.42",6.56183
131.40002,0.219,"9,925.04",6.57795
131.6,0.21933,"9,925.16",6.59387
131.8,0.21967,"9,925.57",6.60993
132,0.21999,"9,923.90",6.6259
132.20002,0.22033,"9,924.02",6.64166
132.40002,0.22067,"9,924.31",6.65779
132.6,0.221,"9,923.67",6.67373
132.8,0.22133,"9,924.14",6.68968
133,0.22167,"9,922.99",6.70567
133.20002,0.22199,"9,922.50",6.72167
133.40002,0.22233,"9,923.03",6.7376
133.6,0.22266,"9,922.72",6.75366
133.8,0.223,"9,923.38",6.7697
134,0.22333,"9,923.20",6.78588
134.20002,0.22366,"9,922.03",6.80193
134.40002,0.224,"9,921.53",6.81801
134.6,0.22433,"9,922.47",6.83426
134.8,0.22466,"9,921.59",6.85046
135,0.225,"9,920.78",6.86643
135.20002,0.22533,"9,921.11",6.88274
135.40002,0.22566,"9,920.21",6.89872
135.6,0.226,"9,920.30",6.91486
135.8,0.22633,"9,920.06",6.93129
136,0.22666,"9,919.45",6.94732
136.20002,0.227,"9,919.20",6.9636
136.40002,0.22733,"9,918.38",6.97962
136.6,0.22766,"9,917.68",6.99588
136.8,0.228,"9,919.16",7.01218
137,0.22833,"9,917.61",7.0285
137.20002,0.22866,"9,916.59",7.04459
137.40002,0.229,"9,917.01",7.06081
137.6,0.22933,"9,915.76",7.07702
137.8,0.22966,"9,915.16",7.0932
138,0.23,"9,916.14",7.10951
138.20002,0.23033,"9,915.04",7.1257
138.40002,0.23066,"9,913.81",7.14175
138.6,0.231,"9,913.99",7.15808
138.8,0.23133,"9,913.16",7.17431
139,0.23167,"9,913.36",7.19059
139.20002,0.232,"9,913.23",7.20684
139.40002,0.23233,"9,912.05",7.22292
139.6,0.23266,"9,911.55",7.23944
139.8,0.233,"9,910.71",7.25564
140,0.23333,"9,910.22",7.27201
140.20002,0.23367,"9,910.41",7.2883
140.40002,0.234,"9,908.69",7.30464
140.6,0.23433,"9,908.14",7.32086
140.8,0.23467,"9,908.36",7.33724
141,0.235,"9,907.00",7.35382
141.20002,0.23533,"9,906.76",7.36991
141.40002,0.23567,"9,906.05",7.38634
141.6,0.23599,"9,904.61",7.40248
141.8,0.23633,"9,904.04",7.41888
142,0.23667,"9,904.30",7.43538
142.20002,0.237,"9,903.57",7.45188
142.40002,0.23733,"9,902.34",7.46813
142.6,0.23767,"9,901.62",7.48456
142.8,0.238,"9,900.52",7.50087
143,0.23833,"9,900.19",7.51741
143.20002,0.23867,"9,899.68",7.53369
143.40002,0.239,"9,898.45",7.55001
143.6,0.23934,"9,897.65",7.5665
143.8,0.23966,"9,896.03",7.58279
144,0.23999,"9,895.29",7.59933
144.20002,0.24033,"9,895.92",7.61585
144.40002,0.24066,"9,894.45",7.63223
144.6,0.241,"9,893.53",7.64506
144.8,0.24133,"9,892.94",7.65236
145,0.24166,"9,890.82",7.66109
145.20002,0.242,"9,890.76",7.4193
145.40002,0.24234,"9,889.92",7.49061
145.6,0.24267,"9,888.31",7.48272
145.8,0.243,"9,887.60",7.45178
146,0.24333,"9,886.03",7.34756
146.20002,0.24366,"9,884.53",7.34237
146.40002,0.244,"9,884.76",7.1848
146.6,0.24433,"9,883.10",7.22135
146.8,0.24466,"9,881.57",7.253
147,0.245,"9,881.16",7.23834
147.20002,0.24533,"9,879.26",7.24981
147.40002,0.24566,"9,878.39",7.24923
147.6,0.246,"9,877.37",-0.68925
147.8,0.24633,"9,875.39",3.77756
148,0.24666,"9,874.76",0.32922
148.20002,0.247,"9,873.55",0.78979
148.40002,0.24733,"9,872.30",0.4552
148.6,0.24767,"9,871.86",1.11102
148.8,0.248,"9,870.20",0.5861
149,0.24833,"9,867.78",0.75248
149.20002,0.24866,"9,867.12",0.26974
149.40002,0.249,"9,865.75",1.26093
149.6,0.24933,"9,864.01",0.65138
149.8,0.24967,"9,863.57",0.63727
150,0.25,"9,860.98",1.00464
150.20002,0.25032,"9,858.82",0.64128
150.40002,0.25066,"9,858.73",2.93311
150.6,0.251,"9,857.09",2.7533
150.8,0.25133,"9,855.12",-0.69914
151,0.25167,"9,853.66",-0.78389
151.20002,0.252,"9,851.42",-1.52564
151.40002,0.25233,"9,849.72",-1.08441
151.6,0.25267,"9,848.19",-1.13438
151.8,0.253,"9,846.54",-1.08284
152,0.25333,"9,845.29",-1.12351
152.20002,0.25367,"9,842.94",-1.11204
152.40002,0.25399,"9,840.81",-1.11393
152.6,0.25433,"9,839.79",-1.12901
152.8,0.25466,"9,837.63",-1.14507
153,0.255,"9,835.43",-1.11318
153.20002,0.25533,"9,834.44",-1.12091
153.40002,0.25566,"9,831.53",-1.13545
153.6,0.256,"9,830.12",-1.1205
153.8,0.25633,"9,828.86",-1.12235
154,0.25666,"9,826.53",-1.13009
154.20002,0.257,"9,824.15",-1.12176
154.40002,0.25733,"9,822.29",-1.12374
154.6,0.25766,"9,819.84",-1.13466
154.8,0.258,"9,818.67",-1.12876
155,0.25834,"9,816.63",-1.12473
155.20002,0.25866,"9,812.80",-1.12614
155.40002,0.259,"9,810.99",-1.12836
155.6,0.25933,"9,808.35",-1.1288
155.8,0.25966,"9,806.66",-1.12784
156,0.26,"9,805.11",-1.12446
156.20002,0.26033,"9,802.13",-1.13035
156.40002,0.26066,"9,798.93",-1.12423
156.6,0.261,"9,797.02",-1.12773
156.8,0.26133,"9,794.26",-1.13427
157,0.26166,"9,792.16",-1.12582
157.20002,0.262,"9,790.30",-1.12814
157.40002,0.26233,"9,786.31",-1.12841
157.6,0.26266,"9,784.07",-1.1238
157.8,0.263,"9,781.68",-1.12948
158,0.26333,"9,779.05",-1.12951
158.20002,0.26367,"9,777.65",-1.12568
158.40002,0.264,"9,774.05",-1.1332
158.6,0.26433,"9,770.72",-1.11251
158.8,0.26467,"9,769.40",-1.13636
159,0.265,"9,766.13",-1.14221
159.20002,0.26533,"9,763.57",-1.11148
159.40002,0.26567,"9,760.80",-1.12714
159.6,0.26599,"9,756.87",-1.13985
159.8,0.26633,"9,754.39",-1.12124
160,0.26667,"9,751.94",-1.12888
160.20002,0.267,"9,748.71",-1.13483
160.40002,0.26733,"9,745.57",-1.12397
160.6,0.26767,"9,742.44",-1.13212
160.8,0.26799,"9,738.56",-1.132
161.00002,0.26833,"9,736.59",-1.12274
161.20002,0.26866,"9,733.79",-1.13373
161.40002,0.269,"9,730.32",-1.1274
161.6,0.26933,"9,727.09",-1.12359
161.8,0.26966,"9,723.75",-1.13902
162.00002,0.26999,"9,720.37",-1.12963
162.20002,0.27034,"9,718.18",-1.12718
162.40002,0.27067,"9,714.08",-1.13125
162.6,0.271,"9,710.23",-1.12922
162.8,0.27133,"9,707.60",-1.12788
163.00002,0.27166,"9,703.19",-1.13275
163.20002,0.272,"9,700.14",-1.12628
163.40002,0.27233,"9,698.05",-1.13028
163.6,0.27266,"9,693.94",-1.12954
163.8,0.273,"9,690.36",-1.13036
164.00002,0.27333,"9,687.23",-1.13189
164.20002,0.27366,"9,683.27",-1.1294
164.40002,0.274,"9,680.03",-1.12897
164.6,0.27433,"9,676.72",-1.12916
164.8,0.27466,"9,671.92",-1.13044
165.00002,0.275,"9,669.06",-1.13111
165.20002,0.27533,"9,665.21",-1.12872
165.40002,0.27566,"9,661.43",-1.13047
165.6,0.276,"9,658.35",-1.12684
165.8,0.27633,"9,653.92",-1.13074
166.00002,0.27666,"9,649.67",-1.13034
166.20002,0.277,"9,647.08",-1.12909
166.40002,0.27733,"9,642.65",-1.13218
166.6,0.27766,"9,639.58",-1.12931
166.8,0.278,"9,635.89",-1.12925
167.00002,0.27833,"9,630.66",-1.13372
167.20002,0.27866,"9,627.75",-1.12599
167.40002,0.279,"9,624.03",-1.13153
167.6,0.27933,"9,619.75",-1.12788
167.8,0.27967,"9,616.00",-1.13233
168.00002,0.28,"9,611.24",-1.13166
168.20002,0.28033,"9,606.15",-1.1186
168.40002,0.28066,"9,603.18",-1.13877
168.6,0.281,"9,599.35",-1.11846
168.8,0.28133,"9,595.38",-1.12516
169.00002,0.28167,"9,591.40",-1.15018
169.20002,0.282,"9,587.24",-1.11695
169.40002,0.28233,"9,583.03",-1.1249
169.6,0.28267,"9,579.35",-1.1469
169.8,0.28299,"9,574.46",-1.11757
170.00002,0.28333,"9,570.28",-1.15066
170.20002,0.28367,"9,566.53",-1.12368
170.40002,0.284,"9,560.83",-1.12934
170.6,0.28433,"9,557.12",-1.1395
170.8,0.28467,"9,553.75",-1.12149
171.00002,0.285,"9,548.14",-1.13998
171.20002,0.28533,"9,544.45",-1.12909
171.40002,0.28566,"9,540.31",-1.12804
171.6,0.28599,"9,535.41",-1.13352
171.8,0.28634,"9,532.19",-1.12773
172.00002,0.28667,"9,526.92",-1.1364
172.20002,0.28699,"9,521.31",-1.12778
172.40002,0.28733,"9,518.03",-1.12442
172.6,0.28766,"9,513.08",-1.13054
172.8,0.28799,"9,508.56",-1.12707
173.00002,0.28834,"9,505.46",-1.13545
173.20002,0.28867,"9,499.56",-1.1304
173.40002,0.289,"9,494.91",-1.12881
173.6,0.28933,"9,491.12",-1.13075
173.8,0.28966,"9,486.29",-1.12536
174.00002,0.29,"9,482.07",-1.13172
174.20002,0.29034,"9,476.83",-1.12807
174.40002,0.29066,"9,471.76",-1.13357
174.6,0.291,"9,467.54",-1.13061
174.8,0.29133,"9,462.69",-1.12966
175.00002,0.29166,"9,458.12",-1.13212
175.20002,0.292,"9,454.38",-1.13152
175.40002,0.29233,"9,448.79",-1.12728
175.6,0.29266,"9,443.73",-1.13539
175.8,0.293,"9,440.02",-1.1261
176.00002,0.29333,"9,434.60",-1.13808
176.20002,0.29367,"9,429.82",-1.12857
176.40002,0.294,"9,425.07",-1.13842
176.6,0.29433,"9,419.76",-1.1207
176.8,0.29466,"9,414.98",-1.13943
177.00002,0.295,"9,410.65",-1.12632
177.20002,0.29533,"9,405.65",-1.13261
177.40002,0.29567,"9,400.37",-1.13403
177.6,0.296,"9,395.48",-1.13238
177.8,0.29633,"9,390.54",-1.13554
178.00002,0.29666,"9,385.85",-1.1296
178.20002,0.297,"9,380.90",-1.13397
178.40002,0.29733,"9,375.92",-1.13134
178.6,0.29767,"9,371.10",-1.13583
178.8,0.298,"9,365.51",-1.12879
179.00002,0.29833,"9,360.29",-1.1367
179.20002,0.29867,"9,356.36",-1.12896
179.40002,0.299,"9,351.10",-1.13074
179.6,0.29933,"9,344.84",-1.13169
179.8,0.29967,"9,340.41",-1.13574
180.00002,0.29999,"9,334.65",-1.12697
180.20002,0.30033,"9,330.19",-1.13257
180.40002,0.30067,"9,326.03",-1.13037
180.6,0.301,"9,319.67",-1.13419
180.8,0.30133,"9,314.64",-1.12712
181.00002,0.30167,"9,309.78",-1.13686
181.20002,0.302,"9,304.19",-1.12759
181.40002,0.30233,"9,299.80",-1.13101
181.6,0.30267,"9,294.17",-1.13498
181.8,0.30299,"9,287.96",-1.12933
182.00002,0.30333,"9,283.43",-1.13479
182.20002,0.30366,"9,278.30",-1.12732
182.40002,0.304,"9,272.95",-1.13666
182.6,0.30434,"9,268.08",-1.1293
182.8,0.30466,"9,261.97",-1.13678
183.00002,0.30499,"9,257.05",-1.12893
183.20002,0.30533,"9,252.15",-1.13307
183.40002,0.30567,"9,245.99",-1.12794
183.6,0.306,"9,240.82",-1.13401
183.8,0.30633,"9,235.51",-1.12973
184.00002,0.30666,"9,230.28",-1.13309
184.20002,0.307,"9,225.03",-1.13125
184.40002,0.30733,"9,220.07",-1.13303
184.6,0.30766,"9,214.46",-1.13226
184.8,0.308,"9,208.81",-1.1365
185.00002,0.30833,"9,202.59",-1.12908
185.20002,0.30866,"9,196.83",-1.13191
185.40002,0.309,"9,192.74",-1.13338
185.6,0.30933,"9,187.03",-1.13351
185.8,0.30966,"9,181.14",-1.13236
186.00002,0.31,"9,176.24",-1.13265
186.20002,0.31033,"9,169.92",-1.13192
186.40002,0.31066,"9,164.74",-1.13183
186.6,0.311,"9,159.81",-1.1318
186.8,0.31133,"9,153.81",-1.1314
187.00002,0.31167,"9,147.88",-1.13167
187.20002,0.312,"9,142.22",-1.13133
187.40002,0.31233,"9,136.52",-1.13312
187.6,0.31267,"9,131.73",-1.1313
187.8,0.313,"9,125.99",-1.12949
188.00002,0.31333,"9,119.37",-1.13421
188.20002,0.31366,"9,114.78",-1.1307
188.40002,0.314,"9,108.51",-1.13598
188.6,0.31433,"9,102.78",-1.13224
188.8,0.31467,"9,098.19",-1.13358
189.00002,0.315,"9,091.53",-1.1313
189.20002,0.31533,"9,085.70",-1.13404
189.40002,0.31567,"9,080.72",-1.13263
189.6,0.31599,"9,074.25",-1.13373
189.8,0.31633,"9,069.18",-1.13289
190.00002,0.31667,"9,063.59",-1.13322
190.20002,0.317,"9,056.52",-1.13478
190.40002,0.31733,"9,051.32",-1.13369
190.6,0.31766,"9,045.29",-1.13396
190.8,0.318,"9,039.83",-1.13132
191.00002,0.31833,"9,034.84",-1.12966
191.20002,0.31867,"9,028.13",-1.13581
191.40002,0.319,"9,021.65",-1.1301
191.6,0.31933,"9,016.53",-1.13507
191.8,0.31966,"9,010.32",-1.1303
192.00002,0.32,"9,004.56",-1.13166
192.20002,0.32034,"8,999.39",-1.12795
192.40002,0.32066,"8,993.16",-1.13441
192.6,0.321,"8,986.94",-1.12985
192.8,0.32133,"8,981.29",-1.13444
193.00002,0.32166,"8,975.21",-1.12928
193.20002,0.322,"8,969.46",-1.12658
193.40002,0.32234,"8,963.21",-1.13616
193.6,0.32266,"8,955.94",-1.13063
193.8,0.323,"8,951.55",-1.13754
194.00002,0.32333,"8,945.46",-1.13674
194.20002,0.32366,"8,939.05",-1.1332
194.40002,0.324,"8,933.99",-1.13035
194.6,0.32433,"8,927.44",-1.13301
194.8,0.32466,"8,920.61",-1.13216
195.00002,0.325,"8,915.66",-1.13347
195.20002,0.32533,"8,909.09",-1.13233
195.40002,0.32567,"8,902.76",-1.13449
195.6,0.326,"8,897.42",-1.13024
195.8,0.32633,"8,890.68",-1.13499
196.00002,0.32666,"8,885.52",-1.13121
196.20002,0.327,"8,879.27",-1.13549
196.40002,0.32733,"8,872.04",-1.13143
196.6,0.32766,"8,866.68",-1.14259
196.8,0.328,"8,860.56",-1.1275
197.00002,0.32833,"8,854.07",-1.14497
197.20002,0.32867,"8,848.59",-1.12753
197.40002,0.329,"8,842.52",-1.14003
197.6,0.32933,"8,834.60",-1.12908
197.8,0.32967,"8,829.52",-1.14055
198.00002,0.33,"8,822.57",-1.12815
198.20002,0.33033,"8,816.89",-1.13333
198.40002,0.33067,"8,811.57",-1.13209
198.6,0.331,"8,804.51",-1.12555
198.8,0.33133,"8,798.24",-1.13966
199.00002,0.33167,"8,792.50",-1.12944
199.20002,0.332,"8,785.54",-1.13318
199.40002,0.33233,"8,779.29",-1.13112
199.6,0.33267,"8,773.65",-1.13057
199.8,0.33299,"8,766.76",-1.13289
200.00002,0.33333,"8,760.66",-1.13368
200.20002,0.33367,"8,754.73",-1.13443
200.40002,0.334,"8,748.58",-1.13475
200.6,0.33433,"8,742.55",-1.13276
200.8,0.33467,"8,735.48",-1.13543
201.00002,0.33499,"8,728.16",-1.12985
201.20002,0.33533,"8,723.33",-1.13712
201.40002,0.33566,"8,716.21",-1.12814
201.6,0.336,"8,710.06",-1.13081
201.8,0.33633,"8,704.17",-1.13338
202.00002,0.33666,"8,696.35",-1.13562
202.20002,0.33699,"8,689.78",-1.13275
202.40002,0.33734,"8,684.75",-1.13856
202.6,0.33766,"8,677.85",-1.13136
202.8,0.338,"8,671.45",-1.13328
203.00002,0.33833,"8,664.67",-1.12954
203.20002,0.33866,"8,657.35",-1.13815
203.40002,0.339,"8,651.90",-1.12605
203.6,0.33933,"8,645.34",-1.14114
203.8,0.33966,"8,638.58",-1.1232
204.00002,0.34,"8,632.17",-1.13482
204.20002,0.34033,"8,625.25",-1.12883
204.40002,0.34066,"8,618.90",-1.13106
204.6,0.341,"8,612.97",-1.13501
204.8,0.34133,"8,606.22",-1.13292
205.00002,0.34166,"8,598.77",-1.13906
205.20002,0.342,"8,592.77",-1.12978
205.40002,0.34233,"8,585.51",-1.13831
205.6,0.34266,"8,579.27",-1.13222
205.8,0.343,"8,573.40",-1.13683
206.00002,0.34333,"8,566.11",-1.13692
206.20002,0.34366,"8,559.29",-1.13351
206.40002,0.344,"8,552.55",-1.13173
206.6,0.34433,"8,545.79",-1.13195
206.8,0.34467,"8,539.87",-1.13419
207.00002,0.345,"8,532.45",-1.13497
207.20002,0.34533,"8,524.96",-1.13056
207.40002,0.34566,"8,519.24",-1.13538
207.6,0.346,"8,512.49",-1.12866
207.8,0.34633,"8,505.56",-1.13645
208.00002,0.34667,"8,499.24",-1.13464
208.20002,0.347,"8,491.19",-1.13473
208.40002,0.34733,"8,484.49",-1.13884
208.6,0.34767,"8,478.36",-1.13634
208.8,0.348,"8,471.22",-1.13439
209.00002,0.34833,"8,464.65",-1.13569
209.20002,0.34867,"8,457.72",-1.13375
209.40002,0.34899,"8,449.81",-1.1348
209.6,0.34933,"8,443.32",-1.13571
209.8,0.34966,"8,437.14",-1.13702
210.00002,0.35,"8,430.52",-1.12925
210.20002,0.35033,"8,423.65",-1.14006
210.40002,0.35066,"8,415.67",-1.1395
210.6,0.35099,"8,408.60",-1.13354
210.8,0.35133,"8,401.79",-1.13397
211.00002,0.35166,"8,394.71",-1.13117
211.20002,0.352,"8,388.40",-1.13205
211.40002,0.35233,"8,381.15",-1.13078
211.6,0.35266,"8,373.38",-1.13391
211.8,0.35299,"8,367.05",-1.13056
212.00002,0.35333,"8,360.35",-1.14474
212.20002,0.35367,"8,352.71",-1.12898
212.40002,0.354,"8,345.51",-1.14223
212.6,0.35433,"8,338.61",-1.12802
212.8,0.35466,"8,330.94",-1.13577
213.00002,0.355,"8,324.34",-1.13089
213.20002,0.35534,"8,317.37",-1.13275
213.40002,0.35567,"8,309.67",-1.13375
213.6,0.356,"8,302.94",-1.13464
213.8,0.35633,"8,295.56",-1.1329
214.00002,0.35666,"8,288.69",-1.13077
214.20002,0.357,"8,281.97",-1.13009
214.40002,0.35733,"8,274.07",-1.13405
214.6,0.35766,"8,265.74",-1.1318
214.8,0.358,"8,259.61",-1.13603
215.00002,0.35833,"8,252.20",-1.13399
215.20002,0.35866,"8,245.43",-1.13451
215.40002,0.359,"8,238.60",-1.13742
215.6,0.35933,"8,230.16",-1.13333
215.8,0.35966,"8,223.00",-1.12925
216.00002,0.36,"8,215.70",-1.13701
216.20002,0.36033,"8,208.04",-1.13274
216.40002,0.36066,"8,201.98",-1.13701
216.6,0.361,"8,193.62",-1.13612
216.8,0.36133,"8,185.80",-1.13298
217.00002,0.36166,"8,178.95",-1.12978
217.20002,0.362,"8,171.27",-1.13727
217.40002,0.36233,"8,164.05",-1.12932
217.6,0.36267,"8,156.98",-1.13388
217.8,0.363,"8,148.91",-1.13255
218.00002,0.36333,"8,140.85",-1.13436
218.20002,0.36367,"8,134.22",-1.13359
218.40002,0.364,"8,126.70",-1.13761
218.6,0.36433,"8,119.04",-1.13175
218.8,0.36467,"8,111.61",-1.13442
219.00002,0.36499,"8,103.41",-1.13275
219.20002,0.36533,"8,096.33",-1.13315
219.40002,0.36567,"8,088.57",-1.13268
219.6,0.366,"8,080.75",-1.13214
219.8,0.36633,"8,073.38",-1.13565
220.00002,0.36666,"8,065.58",-1.13459
220.20002,0.36699,"8,057.89",-1.13549
220.40002,0.36733,"8,050.94",-1.13462
220.6,0.36767,"8,042.98",-1.1356
220.8,0.368,"8,034.60",-1.13499
221.00002,0.36833,"8,027.24",-1.13557
221.20002,0.36866,"8,018.62",-1.13441
221.40002,0.369,"8,011.31",-1.13363
221.6,0.36933,"8,004.26",-1.13148
221.8,0.36967,"7,995.83",-1.13477
222.00002,0.37,"7,987.67",-1.13193
222.20002,0.37033,"7,980.38",-1.13772
222.40002,0.37066,"7,971.86",-1.13086
222.6,0.371,"7,964.70",-1.13651
222.8,0.37134,"7,956.97",-1.12795
223.00002,0.37166,"7,947.78",-1.14257
223.20002,0.372,"7,940.49",-1.12649
223.40002,0.37233,"7,932.38",-1.13893
223.6,0.37267,"7,924.55",-1.13037
223.8,0.373,"7,917.29",-1.1366
224.00002,0.37333,"7,908.54",-1.13308
224.20002,0.37366,"7,900.17",-1.13545
224.40002,0.374,"7,892.87",-1.13348
224.6,0.37433,"7,884.26",-1.13431
224.8,0.37467,"7,877.05",-1.13386
225.00002,0.375,"7,869.17",-1.13432
225.20002,0.37533,"7,859.73",-1.13372
225.40002,0.37566,"7,851.67",-1.13514
225.6,0.376,"7,844.14",-1.13066
225.80002,0.37633,"7,835.99",-1.13715
226.00002,0.37667,"7,828.32",-1.12741
226.20002,0.377,"7,819.67",-1.14281
226.40002,0.37733,"7,810.82",-1.12668
226.6,0.37766,"7,802.60",-1.14252
226.80002,0.378,"7,794.59",-1.12945
227.00002,0.37833,"7,786.82",-1.13635
227.20002,0.37867,"7,778.22",-1.13246
227.40002,0.379,"7,769.44",-1.13823
227.6,0.37933,"7,760.55",-1.13257
227.80002,0.37967,"7,753.09",-1.13424
228.00002,0.38,"7,744.91",-1.13395
228.20002,0.38033,"7,736.01",-1.13151
228.40002,0.38067,"7,727.78",-1.13761
228.6,0.381,"7,718.53",-1.13013
228.80002,0.38133,"7,710.61",-1.14182
229.00002,0.38167,"7,702.12",-1.12597
229.20002,0.382,"7,693.25",-1.14213
229.40002,0.38233,"7,684.86",-1.12683
229.6,0.38266,"7,676.07",-1.13966
229.80002,0.38299,"7,667.50",-1.12853
230.00002,0.38334,"7,660.07",-1.13821
230.20002,0.38367,"7,650.67",-1.13099
230.40002,0.384,"7,641.40",-1.13545
230.6,0.38433,"7,633.43",-1.13384
230.80002,0.38466,"7,623.89",-1.13196
231.00002,0.38499,"7,615.12",-1.13663
231.20002,0.38534,"7,607.70",-1.13368
231.40002,0.38567,"7,597.79",-1.1345
231.6,0.386,"7,588.33",-1.13565
231.80002,0.38633,"7,579.89",-1.13372
232.00002,0.38666,"7,570.64",-1.13586
232.20002,0.387,"7,562.75",-1.13147
232.40002,0.38734,"7,553.27",-1.13678
232.6,0.38766,"7,543.61",-1.12906
232.80002,0.388,"7,535.19",-1.13978
233.00002,0.38833,"7,525.46",-1.12971
233.20002,0.38866,"7,516.75",-1.13753
233.40002,0.389,"7,508.20",-1.13216
233.6,0.38933,"7,498.11",-1.1388
233.80002,0.38966,"7,488.48",-1.13332
234.00002,0.39,"7,479.85",-1.13391
234.20002,0.39033,"7,470.20",-1.13332
234.40002,0.39067,"7,461.17",-1.1326
234.6,0.391,"7,451.96",-1.1314
234.80002,0.39133,"7,441.80",-1.13928
235.00002,0.39166,"7,432.58",-1.13419
235.20002,0.392,"7,423.72",-1.13242
235.40002,0.39233,"7,414.01",-1.13178
235.6,0.39266,"7,404.14",-1.1367
235.80002,0.393,"7,394.43",-1.12973
236.00002,0.39333,"7,384.02",-1.13838
236.20002,0.39366,"7,374.76",-1.12677
236.40002,0.394,"7,365.19",-1.13972
236.6,0.39433,"7,355.31",-1.12693
236.80002,0.39467,"7,345.01",-1.13954
237.00002,0.395,"7,334.57",-1.13573
237.20002,0.39533,"7,324.60",-1.13143
237.40002,0.39567,"7,315.01",-1.13621
237.6,0.396,"7,304.14",-1.13395
237.80002,0.39633,"7,293.54",-1.13103
238.00002,0.39667,"7,283.19",-1.13984
238.20002,0.397,"7,271.26",-1.12728
238.40002,0.39733,"7,258.83",-1.14123
238.486,0.39748,"7,063.52",-1.13876
238.49,0.3975,"6,553.36",-1.13576
238.49402,0.39753,"5,836.82",-1.13088
238.49802,0.39756,"5,033.99",-1.12937
238.50202,0.39759,"4,208.65",-1.13239